Workbook
Name Target: 'Testing Chart'!$P$2:$S$18

Sheet BIO
A1: Student Name | B1: John Barkle
A2: Date Joined | B2: 43757
A3: Student ID
A4: Tuition Program
A5: Current Rank | B5: Dahnbo Nim | C5: 3 Black Stripes
A6: Date of Last Promotion

Sheet Rollup
A1: Start Date | B1: =BIO!$B$2 -> 43757 | C1: Todays Date | D1: =TODAY() -> 45945
A2: Current Rank | B2: =BIO!$C$5 -> 3 Black Stripes | C2: Testing Date | D2: =VLOOKUP(B3,Target,4,0) -> 43847
A3: Target Rank | B3: Yellow Belt | C3: Days Until Testing | D3: =SUM(D2-(TODAY())) -> -2098
A4: Yellow Stripe Requirments
A5: Etiquette | B5: Instruction Date | C5: Days Until Eval | D5: Evaluation Date | E5: Status | F5: Notes
A6: Bowing
A8: Stances (Jah Se) | B8: Instruction Date | C8: Days Until Eval | D8: Evaluation Date | E8: Status | F8: Nickname
A9: Cha Ryuht | B9: =TODAY() -> 45945 | C9: 14 | D9: =SUM(B9+C9) -> 45959 | E9: Proficient | F9: Attention
A10: Kong Kyuk Jah Se | B10: =TODAY() -> 45945 | C10: 14 | D10: =SUM(B10+C10) -> 45959 | E10: Proficient | F10: Left Fighting Stance
A11: Bahng Uh Jah Se | B11: =TODAY() -> 45945 | C11: 14 | D11: =SUM(B11+C11) -> 45959 | E11: Proficient | F11: Right Fighting Stance
A12: Ki Mah Jah Se | B12: =TODAY() -> 45945 | C12: 14 | D12: =SUM(B12+C12) -> 45959 | E12: Proficient | F12: Horse Stance
A13: Juhn Guhl Jah se | B13: =TODAY() -> 45945 | C13: 14 | D13: =SUM(B13+C13) -> 45959 | E13: Proficient | F13: Front Stance
A15: Technique
A16: Sohnh Ppae Ki 1-5 | B16: Instruction Date | C16: Days Until Eval | D16: Evaluation Date | E16: Status | F16: Nickname | G16: Notes: Always Attack Opponents Thumb; Fingers Open WIDE
A17: 1 | B17: =TODAY() -> 45945 | C17: 14 | D17: =SUM(B17+C17) -> 45959 | E17: Proficient | F17: UP | G17: Thumb Up: Rotate up and out.
A18: 2 | B18: =TODAY() -> 45945 | C18: 14 | D18: =SUM(B18+C18) -> 45959 | E18: Proficient | F18: Left | G18: Thumb Left; Rotate Left Horizontally and out
A19: 3 | B19: =TODAY() -> 45945 | C19: 14 | D19: =SUM(B19+C19) -> 45959 | E19: Proficient | F19: Down | G19: Thumb Down; Rotate forward, down, and out
A20: 4 | B20: =TODAY() -> 45945 | C20: 14 | D20: =SUM(B20+C20) -> 45959 | E20: Proficient | F20: Out | G20: Thumb Right, Palm Up Shoot Out 45 degree
A21: 5 | B21: =TODAY() -> 45945 | C21: 14 | D21: =SUM(B21+C21) -> 45959 | E21: Proficient | F21: Circle | G21: Rotate Clockwise, Knife Edge Left
A23: Yellow Belt Requirments
A24: Technique
A25: Ki Bohn Soo 1-5 | B25: Instruction Date | C25: Days Until Eval | D25: Evaluation Date | E25: Status | F25: Nickname | G25: Notes: Point Fingers Where You Want Opponent to Go.
A26: 1 | B26: =TODAY() -> 45945 | C26: 14 | D26: =SUM(B26+C26) -> 45959 | E26: Proficient | F26: Throw Left
A27: 2 | B27: =TODAY() -> 45945 | C27: 14 | D27: =SUM(B27+C27) -> 45959 | E27: Proficient | F27: Spock Shock
A28: 3 | B28: =TODAY() -> 45945 | C28: 14 | D28: =SUM(B28+C28) -> 45959 | E28: Proficient | F28: Hand Shake-Elbow Drop
A29: 4 | B29: =TODAY() -> 45945 | C29: 14 | D29: =SUM(B29+C29) -> 45959 | E29: Proficient | F29: Throw Right
A30: 5 | B30: =TODAY() -> 45945 | C30: 14 | D30: =SUM(B30+C30) -> 45959 | E30: Proficient | F30: Left Over
A31: 6 | B31: =TODAY() -> 45945 | C31: 14 | D31: =SUM(B31+C31) -> 45959 | E31: Proficient | F31: Sudo-Elbow Chop
A32: 7 | B32: =TODAY() -> 45945 | C32: 14 | D32: =SUM(B32+C32) -> 45959 | E32: Proficient | F32: Shoulder Break
A33: 8 | B33: =TODAY() -> 45945 | C33: 14 | D33: =SUM(B33+C33) -> 45959 | E33: Proficient | F33: Y Grab up
A34: 9 | B34: =TODAY() -> 45945 | C34: 14 | D34: =SUM(B34+C34) -> 45959 | E34: Proficient | F34: Hook Knee
A35: 10 | B35: =TODAY() -> 45945 | C35: 14 | D35: =SUM(B35+C35) -> 45959 | E35: Proficient | F35: Temple Thro
A36: 11 | B36: =TODAY() -> 45945 | C36: 14 | D36: =SUM(B36+C36) -> 45959 | E36: Proficient | F36: Chin Throw
A37: 12 | B37: =TODAY() -> 45945 | C37: 14 | D37: =SUM(B37+C37) -> 45959 | E37: Proficient | F37: Throat
... A40: 15 | B40: =TODAY() -> 45945 | C40: 14 | D40: =SUM(B40+C40) -> 45959 | E40: Proficient | F40: High Low
A42: Form
A43: Ki Cho Hyung 4-6
A44: Form
A45: Ki Cho Hyung 1-3
A46: Ki Cho Hyung 1 | B46: Instruction Date | C46: Days Until Eval | D46: Evaluation Date | E46: Status | F46: Notes:
...

Sheet Testing Chart
P1: Belt | Q1: Interval | R1: Period | S1: Test Date
O2: Huin ddi | P2: Yellow Stripe | Q2: 0 | R2: 0 | S2: =BIO!$B$2 -> 43757
O3: Huin ddi | P3: Yellow Belt | Q3: =SUM(S3-S2) -> 90 | R3: 1 | S3: =SUM(S2+90) -> 43847
O4: Norang ddi | P4: Blue Stripe | Q4: =SUM(S4-S3) -> 90 | R4: 2 | S4: =SUM(S3+90) -> 43937
O5: Norang ddi | P5: Blue Belt | Q5: =SUM(S5-S4) -> 90 | R5: 3 | S5: =SUM(S4+90) -> 44027
O6: Cheong ddi | P6: Red Stripe | Q6: =SUM(S6-S5) -> 90 | R6: 4 | S6: =SUM(S5+90) -> 44117
O7: Cheong ddi | P7: Red Belt | Q7: =SUM(S7-S6) -> 90 | R7: 5 | S7: =SUM(S6+90) -> 44207
O8: Hong ddi | P8: Brown Stripe | Q8: =SUM(S8-S7) -> 90 | R8: 6 | S8: =SUM(S7+90) -> 44297
O9: Hong ddi | P9: Brown Belt | Q9: =SUM(S9-S8) -> 90 | R9: 7 | S9: =SUM(S8+90) -> 44387
O10: Ja ddi | P10: 1 Black Stripe | Q10: =SUM(S10-S9) -> 90 | R10: 8 | S10: =SUM(S9+90) -> 44477
O11: Ja ddi | P11: 2 Black Stripes | Q11: =SUM(S11-S10) -> 90 | R11: 9 | S11: =SUM(S10+90) -> 44567
O12: Dahnbo Nim | P12: 3 Black Stripes | Q12: =SUM(S12-S11) -> 90 | R12: 10 | S12: =SUM(S11+90) -> 44657
O13: Dahnbo Nim | P13: 4 Black Stripes | Q13: =SUM(S13-S12) -> 90 | R13: 11 | S13: =SUM(S12+90) -> 44747
O14: Dahnbo Nim | P14: 5 Black Stripes | Q14: =SUM(S14-S13) -> 90 | R14: 12 | S14: =SUM(S13+90) -> 44837
... O18: Jyokyo Nim 1st Dahn | P18: Jyokyo Nim 1st Dahn | Q18: =SUM(S18-S17) -> 90 | R18: 15 | S18: =SUM(S17+90) -> 45197

Sheet White Belt
A1: Start Date | B1: =BIO!$B$2 -> 43757 | C1: Todays Date | D1: =TODAY() -> 45945
A2: Current Rank | B2: White Belt | C2: Testing Date | D2: =VLOOKUP(B3,Target,4,0) -> 43757
A3: Target Rank | B3: Yellow Stripe | C3: Days Until Testing | D3: =SUM(D2-(TODAY())) -> -2188
A5: Yellow Stripe Requirements | B5: Ready to Test?
A6: Sohnh Ppae Ki 1-5
A7: Ki Bohn Soo 1-5
A8: Ki Cho Hyung 1-3
A10: Theory
A11: Etiquette | B11: Instruction Date | C11: Days Until Eval | D11: Evaluation Date | E11: Status | F11: Notes: Customs and Courtesies Displayed By Students of Kuk Sool Won in and out of the Do Jahng
A12: Do Jahng Etiquette | B12: =TODAY() -> 45945 | C12: 14 | D12: =SUM(B12+C12) -> 45959 | E12: Proficient | F12: Customs/Courtesies when entering Leaving the School/Mats, Addressing others, Focus,
A13: Bowing | B13: =TODAY() -> 45945 | C13: 14 | D13: =SUM(B13+C13) -> 45959 | E13: Proficient | F13: Types of Bows and occasions involving bowing
A14: Uniforms | B14: =TODAY() -> 45945 | C14: 14 | D14: =SUM(B14+C14) -> 45959 | E14: Proficient | F14: Proper way to wear the uniform
A15: Foundation | B15: Instruction Date | C15: Days Until Eval | D15: Evaluation Date | E15: Status | F15: Notes:
A16: Five Principles of a Warrior | B16: =TODAY() -> 45945 | C16: 14 | D16: =SUM(B16+C16) -> 45959 | E16: Proficient | F16: Moral Character
A17: Technical | B17: Instruction Date | C17: Days Until Eval | D17: Evaluation Date | E17: Status | F17: Notes:
A18: Forms | B18: =TODAY() -> 45945 | C18: 14 | D18: =SUM(B18+C18) -> 45959 | E18: Proficient
A19: Basic Techniques | B19: =TODAY() -> 45945 | C19: 14 | D19: =SUM(B19+C19) -> 45959 | E19: Proficient
A20: Language | B20: Instruction Date | C20: Days Until Eval | D20: Evaluation Date | E20: Status | F20: Notes:
A21: Counting | B21: =TODAY() -> 45945 | C21: 14 | D21: =SUM(B21+C21) -> 45959 | E21: Proficient | F21: Counting in Korean
A22: Names of Hand Attacks | B22: =TODAY() -> 45945 | C22: 14 | D22: =SUM(B22+C22) -> 45959 | E22: Trained
A24: Technique
A25: Jah Se (Stances) | B25: Instruction Date | C25: Days Until Eval | D25: Evaluation Date | E25: Status | F25: Nickname | G25: Notes: Basic Stances used in Forms and During Techniques; During Practice Stances should be as low as possible
A26: Cha Ryuht | B26: =TODAY() -> 45945 | C26: 14 | D26: =SUM(B26+C26) -> 45959 | E26: Proficient | F26: Attention
A27: Kong Kyuk Jah Se | B27: =TODAY() -> 45945 | C27: 14 | D27: =SUM(B27+C27) -> 45959 | E27: Proficient | F27: Left Fighting Stance
A28: Bahng Uh Jah Se | B28: =TODAY() -> 45945 | C28: 14 | D28: =SUM(B28+C28) -> 45959 | E28: Proficient | F28: Right Fighting Stance
A29: Ki Mah Jah Se | B29: =TODAY() -> 45945 | C29: 14 | D29: =SUM(B29+C29) -> 45959 | E29: Proficient | F29: Horse Stance
A30: Juhn Guhl Jah se | B30: =TODAY() -> 45945 | C30: 14 | D30: =SUM(B30+C30) -> 45959 | E30: Proficient | F30: Front Stance
A31: Crane Stance | B31: =TODAY() -> 45945 | C31: 14 | D31: =SUM(B31+C31) -> 45959 | E31: Proficient | F31: Front Stance
A33: Dahn Juhn Ki (Breating Excercises) | B33: Instruction Date | C33: Days Until Eval | D33: Evaluation Date | E33: Status | F33: Nickname | G33: Notes:
A34: 1 | B34: =TODAY() -> 45945 | C34: 14 | D34: =SUM(B34+C34) -> 45959 | E34: Proficient
A35: 2 | B35: =TODAY() -> 45945 | C35: 14 | D35: =SUM(B35+C35) -> 45959 | E35: Proficient
A37: Ki Cho Jah Ki (Ki Exercise) | B37: Instruction Date | C37: Days Until Eval | D37: Evaluation Date | E37: Status | F37: Notes: "Winging out" Technique to focus and direct the flow of Energy (Ki) through the body
A38: 1 | B38: =TODAY() -> 45945 | C38: 14 | D38: =SUM(B38+C38) -> 45959 | E38: Proficient
A39: 2 | B39: =TODAY() -> 45945 | C39: 14 | D39: =SUM(B39+C39) -> 45959 | E39: Proficient
A40: 3 | B40: =TODAY() -> 45945 | C40: 14 | D40: =SUM(B40+C40) -> 45959 | E40: Proficient
A41: 4 | B41: =TODAY() -> 45945 | C41: 14 | D41: =SUM(B41+C41) -> 45959 | E41: Proficient
A42: 5 | B42: =TODAY() -> 45945 | C42: 14 | D42: =SUM(B42+C42) -> 45959 | E42: Proficient
A43: 6 | B43: =TODAY() -> 45945 | C43: 14 | D43: =SUM(B43+C43) -> 45959 | E43: Proficient
A45: Mohm Puhl Ki (Body Conditioning) | B45: Instruction Date | C45: Days Until Eval | D45: Evaluation Date | E45: Status | F45: Notes: Stretches designed to loosen and strengthen the body to withstand the rigors of training
A46: 1-Forward/Back Stretch | B46: =TODAY() -> 45945 | C46: 14 | D46: =SUM(B46+C46) -> 45959 | E46: Proficient
...

Sheet Yellow Stripe
A1: Start Date | B1: =BIO!$B$2 -> 43757 | C1: Todays Date | D1: =TODAY() -> 45945
A2: Current Rank | B2: Yellow Stripe Belt | C2: Testing Date | D2: =VLOOKUP(B3,Target,4,0) -> 43847
A3: Target Rank | B3: Yellow Belt | C3: Days Until Testing | D3: =SUM(D2-(TODAY())) -> -2098
A5: Yellow Belt Requirments | B5: Ready to Test?
A6: Ki Bohn Soo 1-15
A7: Ki Cho Hyung 1-6
A9: Theory
A10: Etiquette | B10: Instruction Date | C10: Days Until Eval | D10: Evaluation Date | E10: Status | F10: Notes:
A11: Hwarang Do Sesok O-Gye | B11: =TODAY() -> 45945 | C11: 14 | D11: =SUM(B11+C11) -> 45959 | E11: In Progress | F11: Code Of Ethics
A12: Kuk Sool Won Creed | B12: =TODAY() -> 45945 | C12: 14 | D12: =SUM(B12+C12) -> 45959 | E12: Proficient | F12: Student Oath
A13: Foundation | B13: Instruction Date | C13: Days Until Eval | D13: Evaluation Date | E13: Status | F13: Notes:
A14: You-Won-Hwa | B14: =TODAY() -> 45945 | C14: 14 | D14: =SUM(B14+C14) -> 45959 | E14: In Progress
A15: Technical | B15: Instruction Date | C15: Days Until Eval | D15: Evaluation Date | E15: Status | F15: Notes:
A16: Punching | B16: =TODAY() -> 45945 | C16: 14 | D16: =SUM(B16+C16) -> 45959 | E16: Proficient
A17: Kicking | B17: =TODAY() -> 45945 | C17: 14 | D17: =SUM(B17+C17) -> 45959 | E17: Proficient
A18: Promotions: Belts/Stripes | B18: =TODAY() -> 45945 | C18: 14 | D18: =SUM(B18+C18) -> 45959 | E18: Proficient
A19: Language | B19: Instruction Date | C19: Days Until Eval | D19: Evaluation Date | E19: Status | F19: Notes:
A20: Names and Titles | B20: =TODAY() -> 45945 | C20: 14 | D20: =SUM(B20+C20) -> 45959 | E20: Proficient | F20: Addressing Others
A21: Names of Foots Attacks | B21: =TODAY() -> 45945 | C21: 14 | D21: =SUM(B21+C21) -> 45959 | E21: Proficient | F21: Addressing Others
A23: Technique
A24: Jah Se (Stances) | B24: Instruction Date | C24: Days Until Eval | D24: Evaluation Date | E24: Status | F24: Nickname | G24: Notes: Basic Stances
A25: Dragon Stance | B25: =TODAY() -> 45945 | C25: 14 | D25: =SUM(B25+C25) -> 45959 | E25: Proficient
A26: Cat Stance | B26: =TODAY() -> 45945 | C26: 14 | D26: =SUM(B26+C26) -> 45959 | E26: Proficient
A28: Dahn Juhn Ki (Breating Excercises) | B28: Instruction Date | C28: Days Until Eval | D28: Evaluation Date | E28: Status | F28: Nickname | G28: Notes: Breating Excercises
A29: 3 | B29: =TODAY() -> 45945 | C29: 14 | D29: =SUM(B29+C29) -> 45959 | E29: Proficient
A30: 4 | B30: =TODAY() -> 45945 | C30: 14 | D30: =SUM(B30+C30) -> 45959 | E30: Proficient
A32: Nak Bub (Falling Principles) | B32: Instruction Date | C32: Days Until Eval | D32: Evaluation Date | E32: Status | F32: Nickname | G32: Notes: Falling Principles
A33: Goh Yahng Ee Nak Bub | B33: =TODAY() -> 45945 | C33: 14 | D33: =SUM(B33+C33) -> 45959 | E33: Proficient | F33: Cat Roll
A34: Doo Sohn Poong Cha | B34: =TODAY() -> 45945 | C34: 14 | D34: =SUM(B34+C34) -> 45959 | E34: Proficient | F34: Cart Wheel
A36: Soo Ki (Hand Techniques) | B36: Instruction Date | C36: Days Until Eval | D36: Evaluation Date | E36: Status | F36: Nickname | G36: Notes: Basic attacks of the weaponless hand
A37: Four Winds Block | B37: =TODAY() -> 45945 | C37: 14 | D37: =SUM(B37+C37) -> 45959 | E37: Proficient | F37: Four Winds Block
A38: Double High Knife Block | B38: =TODAY() -> 45945 | C38: 17 | D38: =SUM(B38+C38) -> 45962 | E38: Proficient | F38: Double Outside Knife Strike
A39: One Two Punch | B39: =TODAY() -> 45945 | C39: 17 | D39: =SUM(B39+C39) -> 45962 | E39: Proficient | F39: One Two Punch
A40: Circle Back Fist | B40: =TODAY() -> 45945 | C40: 17 | D40: =SUM(B40+C40) -> 45962 | E40: Proficient | F40: One Two Punch
A41: Vertical Spear Hand Strike | B41: =TODAY() -> 45945 | C41: 14 | D41: =SUM(B41+C41) -> 45959 | E41: Proficient | F41: Vertical Spear Hand Strike
A42: Double Knife Chop | B42: =TODAY() -> 45945 | C42: 14 | D42: =SUM(B42+C42) -> 45959 | E42: Proficient | F42: Double Knife Chop
A43: Parallel-Double Palm Strike | B43: =TODAY() -> 45945 | C43: 14 | D43: =SUM(B43+C43) -> 45959 | E43: Proficient | F43: Parallel-Double Palm Strike
A45: Johk Sool (Foot Techniques) | B45: Instruction Date | C45: Days Until Eval | D45: Evaluation Date | E45: Status | F45: Nickname | G45: Notes: Basic attacks using the feet
A46: Knee Kick | B46: =TODAY() -> 45945 | C46: 14 | D46: =SUM(B46+C46) -> 45959 | E46: Proficient | F46: Knee Kick
A47: Round Kick | B47: =TODAY() -> 45945 | C47: 14 | D47: =SUM(B47+C47) -> 45959 | E47: Proficient | F47: Round Kick
...

Sheet Yellow Belt
A1: Promotion Date | C1: Todays Date | D1: =TODAY() -> 45945
A2: Current Rank | B2: Yellow Belt | C2: Testing Date | D2: =VLOOKUP(B3,Target,4,0) -> 43937
A3: Target Rank | B3: Blue Stripe | C3: Days Until Testing | D3: =SUM(D2-(TODAY())) -> -2008
A5: Blue Stripe Requirments | B5: Ready to Test?
A6: Sohn Mohk Soo 1-5
A7: Cho Geup Hyung 1-13
A9: Theory
A10: Etiquette | B10: Instruction Date | C10: Days Until Eval | D10: Evaluation Date | E10: Status | F10: Nickname | G10: Notes:
A11: Handling Weapons
A12: Sparring
A14: Foundation | B14: Instruction Date | C14: Days Until Eval | D14: Evaluation Date | E14: Status | F14: Nickname | G14: Notes:
A15: History of Kuk Sool Weapons
A16: What is Ki | F16: In Korean
A18: Technical | B18: Instruction Date | C18: Days Until Eval | D18: Evaluation Date | E18: Status | F18: Nickname | G18: Notes:
A19: Breathing
A20: Stances
A22: Language | B22: Instruction Date | C22: Days Until Eval | D22: Evaluation Date | E22: Status | F22: Nickname | G22: Notes:
A23: Commands and Terminology
A24: Stances
A26: Technique
A27: Dahn Juhn Ki | B27: Instruction Date | C27: Days Until Eval | D27: Evaluation Date | E27: Status | F27: Nickname | G27: Notes: Breating Excercises
A28: 5 | B28: =TODAY() -> 45945 | C28: 14 | D28: =SUM(B28+C28) -> 45959 | E28: Proficient
A29: 6 | B29: =TODAY() -> 45945 | C29: 14 | D29: =SUM(B29+C29) -> 45959 | E29: Proficient
A31: Nak Bub | B31: Instruction Date | C31: Days Until Eval | D31: Evaluation Date | E31: Status | F31: Nickname | G31: Notes: Falling Principles
A32: Hahn Sohn Poong Cha | B32: =TODAY() -> 45945 | C32: 14 | D32: =SUM(B32+C32) -> 45959 | E32: Proficient | F32: One Hand Cart-wheel
A33: Hahn Sohn Poong Cha | B33: =TODAY() -> 45945 | C33: 14 | D33: =SUM(B33+C33) -> 45959 | E33: Proficient | F33: One Hand Cart-wheel
A35: Soo Ki | B35: Instruction Date | C35: Days Until Eval | D35: Evaluation Date | E35: Status | F35: Nickname | G35: Notes: Hand Techniques; Basic attacks of the weaponless hand
A36: Double Front Block | B36: =TODAY() -> 45945 | C36: 18 | D36: =SUM(B36+C36) -> 45963 | E36: Proficient
A37: Side High Low Cover | B37: =TODAY() -> 45945 | C37: 18 | D37: =SUM(B37+C37) -> 45963 | E37: Proficient
A38: Double Low Knife Block | B38: =TODAY() -> 45945 | C38: 17 | D38: =SUM(B38+C38) -> 45962 | E38: Proficient
A39: Two Handed Knee Cover | B39: =TODAY() -> 45945 | C39: 17 | D39: =SUM(B39+C39) -> 45962 | E39: Proficient
A40: Double Palm Strike | B40: =TODAY() -> 45945 | C40: 17 | D40: =SUM(B40+C40) -> 45962 | E40: Proficient
A41: Inverted Knife Hand | B41: =TODAY() -> 45945 | C41: 17 | D41: =SUM(B41+C41) -> 45962 | E41: Proficient
A42: Knuckle Punch | B42: =TODAY() -> 45945 | C42: 17 | D42: =SUM(B42+C42) -> 45962 | E42: Proficient
A43: Spinning Back Fist | B43: =TODAY() -> 45945 | C43: 17 | D43: =SUM(B43+C43) -> 45962 | E43: Proficient
A44: Inverted Spear Strike | B44: =TODAY() -> 45945 | C44: 17 | D44: =SUM(B44+C44) -> 45962 | E44: Proficient
A45: Horizontal Knife Strike | B45: =TODAY() -> 45945 | C45: 17 | D45: =SUM(B45+C45) -> 45962 | E45: Proficient
A46: Double Hammer fist | B46: =TODAY() -> 45945 | C46: 17 | D46: =SUM(B46+C46) -> 45962 | E46: Proficient
A48: Johk Sool | B48: Instruction Date | C48: Days Until Eval | D48: Evaluation Date | E48: Status | F48: Nickname | G48: Notes: Foot Techniques; Basic attacks using the feet
A51: Sohn Mohk Soo | B51: Instruction Date | C51: Days Until Eval | D51: Evaluation Date | E51: Status | F51: Nickname | G51: Notes Starting Position Opponent grabs Right Hand at the Wrist.
...

Sheet blue stripe
A1: Promotion Date | C1: Todays Date | D1: =TODAY() -> 45945
A2: Current Rank | B2: Blue Stripe Belt | C2: Testing Date | D2: =VLOOKUP(B3,Target,4,0) -> 44027
A3: Target Rank | B3: Blue Belt | C3: Days Until Testing | D3: =SUM(D2-(TODAY())) -> -1918
A5: Blue Belt Requirments | B5: Ready to Test?
A6: Sohn Mohk Soo 11
A7: Cho Geup Hyung 1-24
A9: Theory
A10: Etiquette | B10: Instruction Date | C10: Days Until Eval | D10: Evaluation Date | E10: Status | F10: Nickname | G10: Notes: History, Language,Principles, and Ideology on which all Kuk Sool Won is Founded
A11: Teaching Others
A12: Foundation | B12: Instruction Date | C12: Days Until Eval | D12: Evaluation Date | E12: Status | F12: Nickname | G12: Notes: History, Language,Principles, and Ideology on which all Kuk Sool Won is Founded
A13: Modern History of Kuk Sool Won
A14: Technical | B14: Instruction Date | C14: Days Until Eval | D14: Evaluation Date | E14: Status | F14: Nickname | G14: Notes: History, Language,Principles, and Ideology on which all Kuk Sool Won is Founded
A15: Basic Pressure Points
A16: Blocking
A17: Language | B17: Instruction Date | C17: Days Until Eval | D17: Evaluation Date | E17: Status | F17: Nickname | G17: Notes: History, Language,Principles, and Ideology on which all Kuk Sool Won is Founded
A18: Parts of the Body | B18: =TODAY() -> 45945 | C18: 14 | D18: =SUM(B18+C18) -> 45959 | E18: Trained | F18: In Korean
A19: Directions, Relationships, and Movements | B19: =TODAY() -> 45945 | C19: 14 | D19: =SUM(B19+C19) -> 45959 | E19: Trained
A21: Technique
A22: Dahn Juhn Ki Bub | B22: Instruction Date | C22: Days Until Eval | D22: Evaluation Date | E22: Status | F22: Nickname | G22: Notes: Breathing Excercises
A23: 7 | B23: =TODAY() -> 45945 | C23: 14 | D23: =SUM(B23+C23) -> 45959 | E23: Proficient | F23: One Hand Cart-wheel
A24: 8 | B24: =TODAY() -> 45945 | C24: 14 | D24: =SUM(B24+C24) -> 45959 | E24: Proficient | F24: One Hand Cart-wheel
A26: Nak Bub | B26: Instruction Date | C26: Days Until Eval | D26: Evaluation Date | E26: Status | F26: Nickname | G26: Notes: Falling Principles
A27: Gong Joong Hweh Juhn Nak Bub | B27: =TODAY() -> 45945 | C27: 14 | D27: =SUM(B27+C27) -> 45959 | E27: Proficient | F27: High Roll Fall
A29: Soo Ki | B29: Instruction Date | C29: Days Until Eval | D29: Evaluation Date | E29: Status | F29: Nickname | G29: Notes: Hand Techniques; Basic attacks of the weaponless hand
A30: One two Spin Chop | B30: =TODAY() -> 45945 | C30: 17 | D30: =SUM(B30+C30) -> 45962 | E30: Proficient | F30: One two Spin Chop
A31: Tiger's Mouth | B31: =TODAY() -> 45945 | C31: 14 | D31: =SUM(B31+C31) -> 45959 | E31: Proficient
A32: Tiger's Claw | B32: =TODAY() -> 45945 | C32: 14 | D32: =SUM(B32+C32) -> 45959 | E32: Proficient
A34: Johk Sool | B34: Instruction Date | C34: Days Until Eval | D34: Evaluation Date | E34: Status | F34: Nickname | G34: Notes: Foot Techniques; Basic attacks using the feet
A35: Axe Kick | B35: =TODAY() -> 45945 | C35: 14 | D35: =SUM(B35+C35) -> 45959 | E35: Proficient | F35: Axe Kick
A37: Sohn Mohk Soo | B37: Instruction Date | C37: Days Until Eval | D37: Evaluation Date | E37: Status | G37: Notes: Fundamental Wrist Techniques
A38: 7 | B38: =TODAY() -> 45945 | C38: 14 | D38: =SUM(B38+C38) -> 45959 | E38: Trained | F38: Arm Throw | G38: LF-Cross Step-RH-Rotate Palm Up-LH-Palm Up Wrist Grab; RH-Finger Break;RF-Step in Front-LH/RH-Wrist Grab; Break elbow on Shoulder; Shoulder Throw;(Rolling-Break Fall); Palm Strike
A39: 8 | B39: =TODAY() -> 45945 | C39: 14 | D39: =SUM(B39+C39) -> 45959 | E39: Trained | F39: Front Sweep | G39: RF-Step Behind;RH-Y Grab;LH-Grabs Shoulder;RH-Y Grab-Arm Throw; LF-Ankle Sweep;(Rolling-Break Fall);Kneel on Elbow-back Fist
A40: 9 | B40: =TODAY() -> 45945 | C40: 14 | D40: =SUM(B40+C40) -> 45959 | E40: Trained | F40: Elbow Drop | G40: LF-Cross Step-RH-Rotate Palm Up-LH-Palm Up Wrist Grab; RH-Finger Break; RH Cover Face;Rotate CCW; Wrist Lock Take Down; Kneel;(Back Fall) Pin Elbow, Sudo Strike
A41: 10 | B41: =TODAY() -> 45945 | C41: 14 | D41: =SUM(B41+C41) -> 45959 | E41: Trained | F41: ChestKnee | G41: LF-Cross Step-RH-Rotate Palm Up-LH-Palm Up Wrist Grab; RH-Finger Break; RF-Behind; RH-Elbow Solar Plexus;Cross over Arm Bar;RF-Knee take down;(Back Side Fall);Back Fist
A42: 11 | B42: =TODAY() -> 45945 | C42: 14 | D42: =SUM(B42+C42) -> 45959 | E42: Trained | F42: Indian Burn | G42: RH Circle CCW-Y Grab;LH Hand Grab-Wrist lock,RF-Step In;Point Fingers to Chest; Bend Elow; Rotate Fingers CCW to Floor
A44: Chul Bong | B44: Instruction Date | C44: Days Until Eval | D44: Evaluation Date | E44: Status | F44: Nickname | G44: Notes:
A45: Spinnig 3 | B45: =TODAY() -> 45945 | C45: 14 | D45: =SUM(B45+C45) -> 45959 | E45: Trained
A46: Spinnig 4 | B46: =TODAY() -> 45945 | C46: 14 | D46: =SUM(B46+C46) -> 45959 | E46: Trained
A48: Form
A49: Cho Geup Hyung | B49: Instruction Date | C49: Days Until Eval | D49: Evaluation Date | E49: Status | G49: Notes: Elementary Level Form
...

Sheet blue belt
A1: Promtion Date | C1: Todays Date | D1: =TODAY() -> 45945
A2: Current Rank | B2: Blue Belt | C2: Testing Date | D2: =VLOOKUP(B3,Target,4,0) -> 44117
A3: Target Rank | B3: Red Stripe | C3: Days Until Testing | D3: =SUM(D2-(TODAY())) -> -1828
A5: Red Stripe Requirements | B5: Ready to Test?
A6: Eue Bohk Soo 1-6
A7: Joong Geup Hyung 1/2
A9: Theory
A10: Etiquette | B10: Instruction Date | C10: Days Until Eval | D10: Evaluation Date | E10: Status | F10: Nickname | G10: Notes:
A11: Handling Weapons
A12: Foundation | B12: Instruction Date | C12: Days Until Eval | D12: Evaluation Date | E12: Status | F12: Nickname | G12: Notes:
A13: History of Kuk Sool Weapons
A14: Technical | B14: Instruction Date | C14: Days Until Eval | D14: Evaluation Date | E14: Status | F14: Nickname | G14: Notes:
A15: Locating the Target
A16: Language | B16: Instruction Date | C16: Days Until Eval | D16: Evaluation Date | E16: Status | F16: Nickname | G16: Notes:
A18: Theory | B18: Instruction Date | C18: Days Until Eval | D18: Evaluation Date | E18: Status | F18: Nickname | G18: Notes:
A22: Technique
A23: Dahn Juhn Ki Bub | B23: Instruction Date | C23: Days Until Eval | D23: Evaluation Date | E23: Status | F23: Nickname | G23: Notes: Breating Excercises
A24: 9 | B24: =TODAY() -> 45945 | C24: 14 | D24: =SUM(B24+C24) -> 45959 | E24: Proficient
A25: 10 | B25: =TODAY() -> 45945 | C25: 14 | D25: =SUM(B25+C25) -> 45959 | E25: Proficient
A27: Nak Bub | B27: Instruction Date | C27: Days Until Eval | D27: Evaluation Date | E27: Status | F27: Nickname | G27: Notes: Falling Principles
A28: Gong Joong Ahp Nak Bub | B28: =TODAY() -> 45945 | C28: 14 | D28: =SUM(B28+C28) -> 45959 | E28: Proficient | F28: High Front Fall
A29: Pahl Kum Chi Poong Cha | B29: =TODAY() -> 45945 | C29: 14 | D29: =SUM(B29+C29) -> 45959 | E29: Proficient | F29: Elbow Cart-wheel
A31: Soo Ki | B31: Instruction Date | C31: Days Until Eval | D31: Evaluation Date | E31: Status | F31: Nickname | G31: Notes: Hand Techniques; Basic attacks of the weaponless hand
A32: 24 | B32: =TODAY() -> 45945 | C32: 18 | D32: =SUM(B32+C32) -> 45963 | E32: Proficient | F32: Praying Mantis Block
A33: 15 | B33: =TODAY() -> 45945 | C33: 14 | D33: =SUM(B33+C33) -> 45959 | E33: Proficient | F33: Triple Punch
A34: 17 | B34: =TODAY() -> 45945 | C34: 14 | D34: =SUM(B34+C34) -> 45959 | E34: Proficient | F34: Little Finger hammer Fist
A35: 18 | B35: =TODAY() -> 45945 | C35: 14 | D35: =SUM(B35+C35) -> 45959 | E35: Proficient | F35: One Finger Fist
A37: Johk Sool | B37: Instruction Date | C37: Days Until Eval | D37: Evaluation Date | E37: Status | F37: Nickname | G37: Notes: Foot Techniques; Basic attacks using the feet
A38: High Spin Kick | B38: =TODAY() -> 45945 | C38: 14 | D38: =SUM(B38+C38) -> 45959 | E38: Proficient | F38: High Spin Kick
A39: Jump Front Kick | B39: =TODAY() -> 45945 | C39: 14 | D39: =SUM(B39+C39) -> 45959 | E39: Proficient | F39: Jump Front Kick
A41: Eue Bohk Soo (Clothing Grab) | B41: Instruction Date | C41: Days Until Eval | D41: Evaluation Date | E41: Status | F41: Nickname | G41: Opponet grabs | H41: Opponet grabs
A42: 1 | B42: =TODAY() -> 45945 | C42: 14 | D42: =SUM(B42+C42) -> 45959 | E42: Trained | F42: Wrist Trap | G42: Right Wrist | H42: Open Fingers; Rotate Over CCW (Trap Hand); Thumb Down; Elbow to Chest and Down (Front Fall)
A43: 2 | B43: =TODAY() -> 45945 | C43: 14 | D43: =SUM(B43+C43) -> 45959 | E43: Trained | F43: Forearm Chop | G43: Right Forearm | H43: LH-Grabs PP,Right Hand Escapes;LH-Rotate CCW (Exspose Elbow); Sudo straight Down on Elbow(Front Fall)
A44: 3 | B44: =TODAY() -> 45945 | C44: 14 | D44: =SUM(B44+C44) -> 45959 | E44: Trained | F44: Elbow Trap | G44: Right Bicep | H44: Open Fingers; Rotate Over CCW (Trap Hand); Thumb Down; Elbow to Chest and Down (Front Fall)
A45: 4 | B45: =TODAY() -> 45945 | C45: 14 | D45: =SUM(B45+C45) -> 45959 | E45: Trained | F45: Bicep Trap | G45: Right Shoulder Low | H45: LH-Traps hand;RH-Pins Hand(Fingers UP/Open);Rotate Torso CCW/Down 45 degrees;Kneel (Front Fall)
A46: 5 | B46: =TODAY() -> 45945 | C46: 14 | D46: =SUM(B46+C46) -> 45959 | E46: Trained | F46: Elbow Chop | G46: Right Shoulder High | H46: LH-Grabs PP,Right Hand Escapes;LH-Rotate CCW (Exspose Elbow); Sudo straight Down on Elbow(Front Fall)
A47: 6 | B47: =TODAY() -> 45945 | C47: 14 | D47: =SUM(B47+C47) -> 45959 | E47: Trained | F47: Neck Trap | G47: Behind Neck/Collar | H47: 1/2 Punch; LH Grabs PP;Escape Right;LH-Rotate CCW (Exspose Elbow); Sudo straight Down on Elbow(Front Fall)
A49: Chul Bong | B49: Instruction Date | C49: Days Until Eval | D49: Evaluation Date | E49: Status | F49: Nickname | G49: Notes: Breating Excercises
A50: Spinnig 5
A51: Spinnig 6
...

Sheet red stripe
A1: Promtion Date | C1: Todays Date | D1: =TODAY() -> 45945
A2: Current Rank | B2: Red Stripe | C2: Testing Date | D2: =VLOOKUP(B3,Target,4,0) -> 44207
A3: Target Rank | B3: Red Belt | C3: Days Until Testing | D3: =SUM(D2-(TODAY())) -> -1738
A5: Red Belt Requirements | B5: Ready to Test?
A6: Eue Bohk Soo 1-13
A7: Joong Geup Hyung 1/2
A9: Theory
A10: Etiquette | B10: Instruction Date | C10: Days Until Eval | D10: Evaluation Date | E10: Status | F10: Nickname | G10: Notes:
A12: Foundation | B12: Instruction Date | C12: Days Until Eval | D12: Evaluation Date | E12: Status | F12: Nickname | G12: Notes:
A14: Technical | B14: Instruction Date | C14: Days Until Eval | D14: Evaluation Date | E14: Status | F14: Nickname | G14: Notes:
A16: Language | B16: Instruction Date | C16: Days Until Eval | D16: Evaluation Date | E16: Status | F16: Nickname | G16: Notes:
A18: Technique
A19: Dahn Juhn Ki Bub | B19: Instruction Date | C19: Days Until Eval | D19: Evaluation Date | E19: Status | F19: Nickname | G19: Notes: Breating Excercises
A20: 11 | B20: =TODAY() -> 45945 | C20: 14 | D20: =SUM(B20+C20) -> 45959 | E20: Proficient
A21: 12 | B21: =TODAY() -> 45945 | C21: 14 | D21: =SUM(B21+C21) -> 45959 | E21: Proficient
A23: Nak Bub | B23: Instruction Date | C23: Days Until Eval | D23: Evaluation Date | E23: Status | F23: Nickname | G23: Notes: Falling Principles
A24: Gong Joong Dee Nak Bub | B24: =TODAY() -> 45945 | C24: 14 | D24: =SUM(B24+C24) -> 45959 | E24: Proficient | F24: High Back Fall
A25: Gon Joong Poong Cha | B25: =TODAY() -> 45945 | C25: 14 | D25: =SUM(B25+C25) -> 45959 | E25: Trained | F25: Aerial (No Hand)
A27: Soo Ki | B27: Instruction Date | C27: Days Until Eval | D27: Evaluation Date | E27: Status | F27: Nickname | G27: Notes: Hand Techniques; Basic attacks of the weaponless hand
A28: 19 | B28: =TODAY() -> 45945 | C28: 14 | D28: =SUM(B28+C28) -> 45959 | E28: Proficient | F28: Thumb Strike
A29: 20 | B29: =TODAY() -> 45945 | C29: 14 | D29: =SUM(B29+C29) -> 45959 | E29: Proficient | F29: One Finger Poke
A30: 21 | B30: =TODAY() -> 45945 | C30: 15 | D30: =SUM(B30+C30) -> 45960 | E30: Proficient | F30: Two Finger Poke
A31: 22 | B31: =TODAY() -> 45945 | C31: 16 | D31: =SUM(B31+C31) -> 45961 | E31: Proficient | F31: Five Finger Strike
A33: Johk Sool | B33: Instruction Date | C33: Days Until Eval | D33: Evaluation Date | E33: Status | F33: Nickname | G33: Notes: Foot Techniques; Basic attacks using the feet
A34: Jump Side Kick | B34: =TODAY() -> 45945 | C34: 14 | D34: =SUM(B34+C34) -> 45959 | E34: Proficient
A35: Jump Round Kick | B35: =TODAY() -> 45945 | C35: 14 | D35: =SUM(B35+C35) -> 45959 | E35: Proficient
A37: Eue Bohk Soo 6-13 | B37: Instruction Date | C37: Days Until Eval | D37: Evaluation Date | E37: Status | F37: Nickname | G37: Opponet grabs | H37: Notes:
A38: 7 | B38: =TODAY() -> 45945 | C38: 14 | D38: =SUM(B38+C38) -> 45959 | E38: Trained | F38: Lapel Burn | G38: Both Lapels/Palm up | H38: RH Grabs PP(Trap Cloth)-LH Grabs Hand, Left Foot Steps Through; Rotate Hands CW and Down 45 Degrees (Back Side Fall)
A39: 8 | B39: =TODAY() -> 45945 | C39: 14 | D39: =SUM(B39+C39) -> 45959 | E39: Trained | F39: Lapel Lock | G39: Right Lapel Palm Up | H39: RH Grabs PP(Trap Cloth)-LH Grabs Hand, RF-Steps back; Rotate Hands CW and Down 45 Degrees (Back Side Fall)
A40: 9 | B40: =TODAY() -> 45945 | C40: 14 | D40: =SUM(B40+C40) -> 45959 | E40: Trained | F40: Chest Pin | G40: Center Chest/Palm In | H40: LH-Grabs Thumb down (Trap Cloth);Rotate CCW-RH Grabs Wrist (Point Finger); Rotate Finger in and down
A41: 10 | B41: =TODAY() -> 45945 | C41: 14 | D41: =SUM(B41+C41) -> 45959 | E41: Trained | F41: Over-Belt Burn | G41: Belt Palm down
A42: 11 | B42: =TODAY() -> 45945 | C42: 14 | D42: =SUM(B42+C42) -> 45959 | E42: Trained | F42: Over-Belt Chop | G42: Belt Palm down
A43: 12 | B43: =TODAY() -> 45945 | C43: 14 | D43: =SUM(B43+C43) -> 45959 | E43: Trained | F43: Yuhl-Gyuhl Takedown | G43: Belt Palm Up
A44: 13 | B44: =TODAY() -> 45945 | C44: 14 | D44: =SUM(B44+C44) -> 45959 | E44: Trained | F44: Choon BooTakedown | G44: Belt Palm Up
A46: Chul Bong | B46: Instruction Date | C46: Days Until Eval | D46: Evaluation Date | E46: Status | F46: Nickname | G46: Notes: Weapons Introduction
A47: Striking 1
A48: Striking 2
A50: Form
A51: Joong Geup Hyung 1/2 | B51: Instruction Date | C51: Days Until Eval | D51: Evaluation Date | E51: Status | G51: Notes:
A52: 4 | B52: =TODAY() -> 45945 | C52: 14 | D52: Instruction Date | E52: Trained
...

Sheet red belt
A1: Promotion Date | C1: Todays Date | D1: =TODAY() -> 45945
A2: Current Rank | B2: Red Belt | C2: Testing Date | D2: =VLOOKUP(B3,Target,4,0) -> 44297
A3: Rank | B3: Brown Stripe | C3: Days Until Testing | D3: =SUM(D2-(TODAY())) -> -1648
A5: Brown Stripe Requirements | B5: Ready to Test?
A6: An Sohn Mok Soo 1-6
A7: Goh Geup Hyung 1/2
A9: Theory
A10: Theory | B10: Instruction Date | C10: Days Until Eval | D10: Evaluation Date | E10: Status | F10: Nickname | G10: Notes:
A11: Sah Doh Mu Sool | B11: =TODAY() -> 45945 | C11: 14 | D11: =SUM(B11+C11) -> 45959 | E11: In Progress | F11: Family/Tribal
A14: Technique
A15: Nak Bub | B15: Instruction Date | C15: Days Until Eval | D15: Evaluation Date | E15: Status | F15: Nickname | G15: Notes: Falling Principles
A16: Gong Joong Hweh Juhn Nak Bub | B16: =TODAY() -> 45945 | C16: 14 | D16: =SUM(B16+C16) -> 45959 | E16: Proficient | F16: High Roll Fall
A18: Soo Ki | B18: Instruction Date | C18: Days Until Eval | D18: Evaluation Date | E18: Status | F18: Nickname | G18: Notes: Hand Techniques; Basic attacks of the weaponless hand
B19: =TODAY() -> 45945 | C19: 14 | D19: =SUM(B19+C19) -> 45959 | E19: Proficient
A21: Johk Sool | B21: Instruction Date | C21: Days Until Eval | D21: Evaluation Date | E21: Status | F21: Nickname | G21: Notes: Foot Techniques; Basic attacks using the feet
A22: Back Kick | B22: =TODAY() -> 45945 | C22: 14 | D22: =SUM(B22+C22) -> 45959 | E22: Proficient
A23: Hook Kick | B23: =TODAY() -> 45945 | C23: 14 | D23: =SUM(B23+C23) -> 45959 | E23: Proficient
A25: An Sohn Mok Soo 1-6 | B25: Instruction Date | C25: Days Until Eval | D25: Evaluation Date | E25: Status | F25: Nickname | G25: Notes:
A26: 1 | B26: =TODAY() -> 45945 | C26: 14 | D26: =SUM(B26+C26) -> 45959 | E26: Trained | F26: Fingers
A27: 2 | B27: =TODAY() -> 45945 | C27: 14 | D27: =SUM(B27+C27) -> 45959 | E27: Trained | F27: Elbow Drop
A28: 3 | B28: =TODAY() -> 45945 | C28: 14 | D28: =SUM(B28+C28) -> 45959 | E28: Trained | F28: Backstreet
A29: 4 | B29: =TODAY() -> 45945 | C29: 14 | D29: =SUM(B29+C29) -> 45959 | E29: Trained | F29: Elbow Chop
A30: 5 | B30: =TODAY() -> 45945 | C30: 14 | D30: =SUM(B30+C30) -> 45959 | E30: Trained | F30: Hyperfoot
A31: 6 | B31: =TODAY() -> 45945 | C31: 14 | D31: =SUM(B31+C31) -> 45959 | E31: Trained | F31: Indian Burm
A33: Chul Bong | B33: Instruction Date | C33: Days Until Eval | D33: Evaluation Date | E33: Status | F33: Nickname | G33: Notes: Weapons Introduction
A34: Striking 3 | B34: =TODAY() -> 45945 | C34: 14 | D34: =SUM(B34+C34) -> 45959 | E34: Trained
A35: Striking 4 | B35: =TODAY() -> 45945 | C35: 14 | D35: =SUM(B35+C35) -> 45959 | E35: Trained
A36: Form
A37: Goh Geup Hyung 1/2 | B37: Instruction Date | C37: Days Until Eval | D37: Evaluation Date | E37: Status | F37: Notes:
A38: 1 | B38: =TODAY() -> 45945 | C38: 14 | D38: =SUM(B38+C38) -> 45959 | E38: Trained
A39: 2 | B39: =TODAY() -> 45945 | C39: 14 | D39: =SUM(B39+C39) -> 45959 | E39: Trained
A40: 3 | B40: =TODAY() -> 45945 | C40: 14 | D40: =SUM(B40+C40) -> 45959 | E40: Trained

Sheet Red Stripe Belt
A1: Promotion Date | C1: Todays Date | D1: =TODAY() -> 45945
A2: Current Rank | B2: Brown Stripe | C2: Testing Date | D2: =VLOOKUP(B3,Target,4,0) -> 44387
A3: Rank | B3: Brown Belt | C3: Days Until Testing | D3: =SUM(D2-(TODAY())) -> -1558
A5: Brown Belt Requirements | B5: Ready to Test?
A6: Maek Chi Ki 1-15
A7: Goh Geup Hyung 1/2
A8: High Spin Kick
A10: Theory
B11: Instruction Date | C11: Days Until Eval | D11: Evaluation Date | E11: Status | F11: Nickname | G11: Notes:
A12: Bool Kyo MU Sool | F12: Buddhist Temple
A17: Technique
A18: Nak Bub | B18: Instruction Date | C18: Days Until Eval | D18: Evaluation Date | E18: Status | F18: Nickname | G18: Notes: Falling Principles
A19: Doo Sohn Aho Poong Cha | B19: =TODAY() -> 45945 | C19: 14 | D19: =SUM(B19+C19) -> 45959 | E19: Proficient | F19: Hand Spring
A21: Soo Ki | B21: Instruction Date | C21: Days Until Eval | D21: Evaluation Date | E21: Status | F21: Nickname | G21: Notes: Hand Techniques; Basic attacks of the weaponless hand
A22: V-Double Palm Strike | B22: =TODAY() -> 45945 | C22: 14 | D22: =SUM(B22+C22) -> 45959 | E22: Proficient
A24: Johk Sool | B24: Instruction Date | C24: Days Until Eval | D24: Evaluation Date | E24: Status | F24: Nickname | G24: Notes: Foot Techniques; Basic attacks using the feet
A25: Inverted Stomp Kick | B25: =TODAY() -> 45945 | C25: 14 | D25: =SUM(B25+C25) -> 45959 | E25: Proficient
A26: Inverted Round Kick | B26: =TODAY() -> 45945 | C26: 14 | D26: =SUM(B26+C26) -> 45959 | E26: Proficient
A27: Inverted Side kick | B27: =TODAY() -> 45945 | C27: 14 | D27: =SUM(B27+C27) -> 45959 | E27: Proficient
B28: =TODAY() -> 45945 | C28: 14 | D28: =SUM(B28+C28) -> 45959 | E28: Proficient
B29: =TODAY() -> 45945 | C29: 14 | D29: =SUM(B29+C29) -> 45959 | E29: Proficient
A31: Maek Chi Ki | B31: Instruction Date | C31: Days Until Eval | D31: Evaluation Date | E31: Status | F31: Nickname | G31: Notes:
A32: 1 | B32: =TODAY() -> 45945 | C32: 14 | D32: =SUM(B32+C32) -> 45959 | E32: Trained | F32: Yuhl Gyuhl
A33: 2 | B33: =TODAY() -> 45945 | C33: 14 | D33: =SUM(B33+C33) -> 45959 | E33: Trained | F33: Soo Sahm
A34: 3 | B34: =TODAY() -> 45945 | C34: 14 | D34: =SUM(B34+C34) -> 45959 | E34: Trained | F34: Chuhn Boo
A35: 4 | B35: =TODAY() -> 45945 | C35: 14 | D35: =SUM(B35+C35) -> 45959 | E35: Trained | F35: Geuk Chuhn
A36: 5 | B36: =TODAY() -> 45945 | C36: 14 | D36: =SUM(B36+C36) -> 45959 | E36: Trained | F36: Hohn Soo
A37: 6 | B37: =TODAY() -> 45945 | C37: 14 | D37: =SUM(B37+C37) -> 45959 | E37: Trained | F37: Gaek Joo In
A38: 7 | B38: =TODAY() -> 45945 | C38: 14 | D38: =SUM(B38+C38) -> 45959 | E38: Trained | F38: Hahn Soo
A39: 8 | B39: =TODAY() -> 45945 | C39: 14 | D39: =SUM(B39+C39) -> 45959 | E39: Trained | F39: Dae Po
A40: 9 | B40: =TODAY() -> 45945 | C40: 14 | D40: =SUM(B40+C40) -> 45959 | E40: Trained | F40: UmKyo
A41: 10 | B41: =TODAY() -> 45945 | C41: 14 | D41: =SUM(B41+C41) -> 45959 | E41: Trained | F41: Goo Mi
A42: 11 | B42: =TODAY() -> 45945 | C42: 14 | D42: =SUM(B42+C42) -> 45959 | E42: Trained | F42: Yuhm Chuhn
A43: 12 | B43: =TODAY() -> 45945 | C43: 14 | D43: =SUM(B43+C43) -> 45959 | E43: Trained | F43: Jahng Moon
... A46: 15 | B46: =TODAY() -> 45945 | C46: 14 | D46: =SUM(B46+C46) -> 45959 | E46: Trained | F46: Yoo Geun
A48: Bong Do Liki | B48: Instruction Date | C48: Days Until Eval | D48: Evaluation Date | E48: Status | F48: Nickname | G48: Notes: Staff Spinning Techiques
A49: Spinning 1 | B49: =TODAY() -> 45945 | C49: 14 | D49: =SUM(B49+C49) -> 45959 | E49: Trained | F49: Spinnig 1
A50: Spinning 2 | B50: Spinnig 1 | C50: Spinnig 1 | D50: Spinnig 1 | E50: Spinnig 1 | F50: Spinnig 1
A51: Spinning 3 | B51: Spinnig 1 | C51: Spinnig 1 | D51: Spinnig 1 | E51: Spinnig 1 | F51: Spinnig 1
A53: Form
...

Sheet Brown Belt
A1: Promotion Date | C1: Todays Date | D1: =TODAY() -> 45945
A2: Current Rank | B2: Brown Belt | C2: Testing Date | D2: =VLOOKUP(B3,Target,4,0) -> 44477
A3: Target Rank | B3: 1 Black Stripe | C3: Days Until Testing | D3: =SUM(D2-(TODAY())) -> -1468
A5: 1 Black Stripe Requirements | B5: Ready to Test?
A6: Maek Cha Ki 1-15
A7: Dae Geup Hyung 1/2
A8: Low Spin Kick
A10: Theory
B11: Instruction Date | C11: Days Until Eval | D11: Evaluation Date | E11: Status | F11: Nickname | G11: Notes:
A12: Koong Joong Mu Sool | D12: 44832 | E12: Trained | F12: Korean Royal Palace
D13: 44832 | E13: Trained
D14: 44832 | E14: Trained
D15: 44832 | E15: Trained
A17: Technique
A18: Soo Ki | B18: Instruction Date | C18: Days Until Eval | D18: Evaluation Date | E18: Status | F18: Nickname | G18: Notes:
D19: 44832
A21: Johk Sool | B21: Instruction Date | C21: Days Until Eval | D21: Evaluation Date | E21: Status | F21: Nickname | G21: Notes:
A22: Jump Spin Kick | D22: 44832 | E22: Trained
A23: Low Spin Kick | D23: 44832 | E23: Trained
A25: Maek Cha Ki | B25: Instruction Date | C25: Days Until Eval | D25: Evaluation Date | E25: Status | F25: Nickname | G25: Notes:
A26: 1 | B26: =TODAY() -> 45945 | C26: 14 | D26: 44832 | E26: Trained | F26: Sam Um Kyo
A27: 2 | B27: =TODAY() -> 45945 | C27: 14 | D27: 44832 | E27: Trained | F27: Dohk Bi
A28: 3 | B28: =TODAY() -> 45945 | C28: 14 | D28: 44832 | E28: Trained | F28: Wee Joong
A29: 4 | B29: =TODAY() -> 45945 | C29: 14 | D29: 44832 | E29: Trained | F29: Hyul Hae
A30: 5 | B30: =TODAY() -> 45945 | C30: 14 | D30: 44832 | E30: Trained | F30: Jahng Moon
A31: 6 | B31: =TODAY() -> 45945 | C31: 14 | D31: 44832 | E31: Trained | F31: Geuk Chuhn
A32: 7 | B32: =TODAY() -> 45945 | C32: 14 | D32: 44832 | E32: Trained | F32: Ki Hae
A33: 8 | B33: =TODAY() -> 45945 | C33: 14 | D33: 44832 | E33: Trained | F33: Goo Mi
A34: 9 | B34: =TODAY() -> 45945 | C34: 14 | D34: 44832 | E34: Trained | F34: Yuhm Chuhn
A35: 10 | B35: =TODAY() -> 45945 | C35: 14 | D35: 44832 | E35: Trained | F35: Hohn Soo
A36: 11 | B36: =TODAY() -> 45945 | C36: 14 | D36: 44832 | E36: Trained | F36: You Geun
A37: 12 | B37: =TODAY() -> 45945 | C37: 14 | D37: 44832 | E37: Trained | F37: Ah Moon
... A40: 15 | B40: =TODAY() -> 45945 | C40: 14 | D40: 44832 | E40: Trained | F40: Yahng Neung Chung
A42: Joo Muhk Maga Ki Bon Soo | B42: Instruction Date | C42: Days Until Eval | D42: Evaluation Date | E42: Status | F42: Nickname | G42: Notes:
A43: 1 | B43: =TODAY() -> 45945 | C43: 14 | D43: =SUM(B43+C43) -> 45959 | E43: Trained | F43: Throw Right
A44: 2 | B44: =TODAY() -> 45945 | C44: 14 | D44: =SUM(B44+C44) -> 45959 | E44: Trained | F44: Throw Left
A45: 3 | B45: =TODAY() -> 45945 | C45: 14 | D45: =SUM(B45+C45) -> 45959 | E45: Trained | F45: Elbow Throw
A46: 4 | B46: =TODAY() -> 45945 | C46: 14 | D46: =SUM(B46+C46) -> 45959 | E46: Trained | F46: Cross Block Up
A47: 5 | B47: =TODAY() -> 45945 | C47: 14 | D47: =SUM(B47+C47) -> 45959 | E47: Trained | F47: Cross Block down
A48: 6 | B48: =TODAY() -> 45945 | C48: 14 | D48: =SUM(B48+C48) -> 45959 | E48: Trained | F48: Circle Block Chop
...

Sheet 1 Black Stripe
A1: Promotion Date | C1: Todays Date | D1: =TODAY() -> 45945
A2: Current Rank | B2: 1 Black Stripe | C2: Testing Date | D2: =VLOOKUP(B3,Target,4,0) -> 44567
A3: Target Rank | B3: 2 Black Stripes | C3: Days Until Testing | D3: =SUM(D2-(TODAY())) -> -1378
A5: 2 Black Stripes Requirements | B5: Ready to Test?
A6: Maek Cha Ki 1-15
A7: Dae Geup Hyung 1/2
A9: Theory
B10: Instruction Date | C10: Days Until Eval | D10: Evaluation Date | E10: Status | F10: Nickname | G10: Notes:
A11: Koong Joong Mu Sool | D11: 44832 | E11: Trained | F11: Korean Royal Palace
D12: 44832 | E12: Trained
D13: 44832 | E13: Trained
D14: 44832 | E14: Trained
A16: Technique
A17: Soo Ki | B17: Instruction Date | C17: Days Until Eval | D17: Evaluation Date | E17: Status | F17: Nickname | G17: Notes:
D18: 44832
A20: Johk Sool | B20: Instruction Date | C20: Days Until Eval | D20: Evaluation Date | E20: Status | F20: Nickname | G20: Notes:
A21: R-Jump Round Kick | D21: 44832 | E21: Trained
A22: Jump Spin Side Kick | D22: 44832 | E22: Trained
A24: Joo Muhk Maga Ki Bon Soo | B24: Instruction Date | C24: Days Until Eval | D24: Evaluation Date | E24: Status | F24: Nickname | G24: Notes:
A25: 1 | B25: =TODAY() -> 45945 | C25: 14 | D25: =SUM(B25+C25) -> 45959 | E25: Trained | F25: Throw Right
A26: 2 | B26: =TODAY() -> 45945 | C26: 14 | D26: =SUM(B26+C26) -> 45959 | E26: Trained | F26: Throw Left
A27: 3 | B27: =TODAY() -> 45945 | C27: 14 | D27: =SUM(B27+C27) -> 45959 | E27: Trained | F27: Elbow Throw
A28: 4 | B28: =TODAY() -> 45945 | C28: 14 | D28: =SUM(B28+C28) -> 45959 | E28: Trained | F28: Cross Block Up
A29: 5 | B29: =TODAY() -> 45945 | C29: 14 | D29: =SUM(B29+C29) -> 45959 | E29: Trained | F29: Cross Block down
A30: 6 | B30: =TODAY() -> 45945 | C30: 14 | D30: =SUM(B30+C30) -> 45959 | E30: Trained | F30: Circle Block Chop
A31: 7 | B31: =TODAY() -> 45945 | C31: 14 | D31: =SUM(B31+C31) -> 45959 | E31: Trained | F31: Cover down Left
A32: 8 | B32: =TODAY() -> 45945 | C32: 14 | D32: =SUM(B32+C32) -> 45959 | E32: Trained | F32: Knife Attack
A33: 9 | B33: =TODAY() -> 45945 | C33: 14 | D33: =SUM(B33+C33) -> 45959 | E33: Trained | F33: Hook Knee
A34: 10 | B34: =TODAY() -> 45945 | C34: 14 | D34: =SUM(B34+C34) -> 45959 | E34: Trained | F34: Temple Thro
A35: 11 | B35: =TODAY() -> 45945 | C35: 14 | D35: =SUM(B35+C35) -> 45959 | E35: Trained | F35: Chin Throw
A36: 12 | B36: =TODAY() -> 45945 | C36: 14 | D36: =SUM(B36+C36) -> 45959 | E36: Trained | F36: Throat
... A39: 15 | B39: =TODAY() -> 45945 | C39: 14 | D39: =SUM(B39+C39) -> 45959 | E39: Trained | F39: High Low
A41: Bong Do Liki | B41: Instruction Date | C41: Days Until Eval | D41: Evaluation Date | E41: Status | F41: Nickname | G41: Notes:
A42: Spinning 4
A43: Spinning 5
A45: Form
A46: Dae Geup Hyung 1/2 | B46: Instruction Date | C46: Days Until Eval | D46: Evaluation Date | E46: Status | F46: Notes:
A47: 4 | B47: =TODAY() -> 45945 | C47: 14 | D47: Instruction Date | E47: Trained
A48: 5 | B48: =TODAY() -> 45945 | C48: 14 | D48: Instruction Date | E48: Trained
A49: 6 | B49: =TODAY() -> 45945 | C49: 14 | D49: Instruction Date | E49: Trained

Sheet 2 Black Stripes
A1: Promotion Date | C1: Todays Date | D1: =TODAY() -> 45945
A2: Current Rank | B2: 2 Black Stripes | C2: Testing Date | D2: =VLOOKUP(B3,Target,4,0) -> 44657
A3: Target Rank | B3: 3 Black Stripes | C3: Days Until Testing | D3: =SUM(D2-(TODAY())) -> -1288
A5: 3 Black Stripes Requirements | B5: Ready to Test?
A6: Joong Geup Sohn Mok Soo
A7: Guhm Moo Hyung
A9: Nak Bub | B9: Instruction Date | C9: Days Until Eval | D9: Evaluation Date | E9: Status | F9: Nickname | G9: Notes: Falling Principles
A10: Ahp Gong Joong Hweh Juhn Nak Bub | B10: =TODAY() -> 45945 | C10: 14 | D10: =SUM(B10+C10) -> 45959 | E10: Proficient | F10: Front Flip
A12: Technique
A13: Joong Geup Sohn Mok Soo | B13: Instruction Date | C13: Days Until Eval | D13: Evaluation Date | E13: Status | F13: Notes:
A14: 1 | B14: =TODAY() -> 45945 | C14: 14 | D14: Instruction Date | E14: Trained
A15: 2 | B15: =TODAY() -> 45945 | C15: 14 | D15: Instruction Date | E15: Trained
A16: 3 | B16: =TODAY() -> 45945 | C16: 14 | D16: Instruction Date | E16: Trained
A17: 4 | B17: =TODAY() -> 45945 | C17: 14 | D17: Instruction Date | E17: Trained
A18: 5 | B18: =TODAY() -> 45945 | C18: 14 | D18: Instruction Date | E18: Trained
A19: 6 | B19: =TODAY() -> 45945 | C19: 14 | D19: Instruction Date | E19: Trained
A20: 7 | B20: =TODAY() -> 45945 | C20: 14 | D20: Instruction Date | E20: Trained
A21: 8 | B21: =TODAY() -> 45945 | C21: 14 | D21: Instruction Date | E21: Trained
A22: 9 | B22: =TODAY() -> 45945 | C22: 14 | D22: Instruction Date | E22: Trained
A23: 10 | B23: =TODAY() -> 45945 | C23: 14 | D23: Instruction Date | E23: Trained
A24: 11 | B24: =TODAY() -> 45945 | C24: 14 | D24: Instruction Date | E24: Trained
A25: 12 | B25: =TODAY() -> 45945 | C25: 14 | D25: Instruction Date | E25: Trained
... A28: 15 | B28: =TODAY() -> 45945 | C28: 14 | D28: Instruction Date | E28: Trained
A30: Bohng Dol-liki (Staff Spinning) | B30: Instruction Date | C30: Days Until Eval | D30: Evaluation Date | E30: Status | F30: Notes:
A31: 6 | B31: =TODAY() -> 45945 | C31: 14 | D31: Instruction Date | E31: Trained | F31: Rotate Right
A32: 7 | B32: =TODAY() -> 45945 | C32: 14 | D32: Instruction Date | E32: Trained | F32: Rotate Back/Right Side
A33: 8 | B33: =TODAY() -> 45945 | C33: 14 | D33: Instruction Date | E33: Trained | F33: Rotate Back/Left Side
A35: Form
A36: Guhm Moo Hyung | B36: Instruction Date | C36: Days Until Eval | D36: Evaluation Date | E36: Status | F36: Notes:
A37: 1 | B37: =TODAY() -> 45945 | C37: 14 | D37: Instruction Date | E37: Trained
A38: 2 | B38: =TODAY() -> 45945 | C38: 14 | D38: Instruction Date | E38: Trained

Sheet 3 Black Stripes
A1: Promotion Date | C1: Todays Date | D1: =TODAY() -> 45945
A2: Current Rank | B2: 3 Black Stripes | C2: Testing Date | D2: =VLOOKUP(B3,Target,4,0) -> 44747
A3: Target Rank | B3: 4 Black Stripes | C3: Days Until Testing | D3: =SUM(D2-(TODAY())) -> -1198
A5: 4 Black Stripes Requirement | B5: Ready to Test?
A6: Ap Eue Bohk Soo
A7: Guhm Moo Hyung
A9: Theory
B10: Instruction Date | C10: Days Until Eval | D10: Evaluation Date | E10: Status | F10: Notes:
A14: Technique
A15: Ap Eue Bohk Soo | B15: Instruction Date | C15: Days Until Eval | D15: Evaluation Date | E15: Status | F15: Notes:
A16: 1 | B16: =TODAY() -> 45945 | C16: 14 | D16: Instruction Date | E16: In Progress
A17: 2 | B17: =TODAY() -> 45945 | C17: 14 | D17: Instruction Date | E17: In Progress
A18: 3 | B18: =TODAY() -> 45945 | C18: 14 | D18: Instruction Date | E18: In Progress
A19: 4 | B19: =TODAY() -> 45945 | C19: 14 | D19: Instruction Date | E19: In Progress
A20: 5 | B20: =TODAY() -> 45945 | C20: 14 | D20: Instruction Date | E20: Untrained
A21: 6 | B21: =TODAY() -> 45945 | C21: 14 | D21: Instruction Date | E21: Untrained
A22: 7 | B22: =TODAY() -> 45945 | C22: 14 | D22: Instruction Date | E22: Untrained
A23: 8 | B23: =TODAY() -> 45945 | C23: 14 | D23: Instruction Date | E23: Untrained
A24: 9 | B24: =TODAY() -> 45945 | C24: 14 | D24: Instruction Date | E24: Untrained
A25: 10 | B25: =TODAY() -> 45945 | C25: 14 | D25: Instruction Date | E25: Untrained
A26: 11 | B26: =TODAY() -> 45945 | C26: 14 | D26: Instruction Date | E26: Untrained
A27: 12 | B27: =TODAY() -> 45945 | C27: 14 | D27: Instruction Date | E27: Untrained
... A35: 20 | B35: =TODAY() -> 45945 | C35: 14 | D35: Instruction Date | E35: Untrained
A37: Bohng Dol-liki (Staff Spinning) | B37: Instruction Date | C37: Days Until Eval | D37: Evaluation Date | E37: Status | F37: Notes:
A38: 9a/9b | B38: =TODAY() -> 45945 | C38: 14 | D38: Instruction Date | E38: Trained | F38: Cross Front Right Hand/Cross Front Left Hand
A39: 10a/10b | B39: =TODAY() -> 45945 | C39: 14 | D39: Instruction Date | E39: Trained | F39: Behind Back to Right/Behind Back to Left
A41: Technique
A42: Guhm Moo Hyung | B42: Instruction Date | C42: Days Until Eval | D42: Evaluation Date | E42: Status | F42: Notes:
A43: 4 | B43: =TODAY() -> 45945 | C43: 14 | D43: Instruction Date | E43: Trained
A44: 5 | B44: =TODAY() -> 45945 | C44: 14 | D44: Instruction Date | E44: Trained

Sheet 4 Black Stripes
A1: Promotion Date | C1: Todays Date | D1: =TODAY() -> 45945
A2: Current Rank | B2: 4 Black Stripes | C2: Testing Date | D2: =VLOOKUP(B3,Target,4,0) -> 44837
A3: Target Rank | B3: 5 Black Stripes | C3: Days Until Testing | D3: =SUM(D2-(TODAY())) -> -1108
A5: 5 Black Stripes Requirements | B5: Ready to Test?
A6: Dae Eue Bok Soo
A7: N/A
A9: Theory
B10: Instruction Date | C10: Days Until Eval | D10: Evaluation Date | E10: Status | F10: Notes:
A14: Technique
A15: Dae Eue Bok Soo | B15: Instruction Date | C15: Days Until Eval | D15: Evaluation Date | E15: Status | F15: Notes:
A16: 1 | B16: =TODAY() -> 45945 | C16: 14 | D16: Instruction Date | E16: Untrained
A17: 2 | B17: =TODAY() -> 45945 | C17: 14 | D17: Instruction Date | E17: Untrained
A18: 3 | B18: =TODAY() -> 45945 | C18: 14 | D18: Instruction Date | E18: Untrained
A19: 4 | B19: =TODAY() -> 45945 | C19: 14 | D19: Instruction Date | E19: Untrained
A20: 5 | B20: =TODAY() -> 45945 | C20: 14 | D20: Instruction Date | E20: Untrained
A21: 6 | B21: =TODAY() -> 45945 | C21: 14 | D21: Instruction Date | E21: Untrained
A22: 7 | B22: =TODAY() -> 45945 | C22: 14 | D22: Instruction Date | E22: Untrained
A23: 8 | B23: =TODAY() -> 45945 | C23: 14 | D23: Instruction Date | E23: Untrained
A24: 9 | B24: =TODAY() -> 45945 | C24: 14 | D24: Instruction Date | E24: Untrained
A25: 10 | B25: =TODAY() -> 45945 | C25: 14 | D25: Instruction Date | E25: Untrained
A26: 11 | B26: =TODAY() -> 45945 | C26: 14 | D26: Instruction Date | E26: Untrained
A27: 12 | B27: =TODAY() -> 45945 | C27: 14 | D27: Instruction Date | E27: Untrained
... A38: 23 | B38: =TODAY() -> 45945 | C38: 14 | D38: Instruction Date | E38: Untrained
A40: Bohng Dol-liki (Staff Spinning) | B40: Instruction Date | C40: Days Until Eval | D40: Evaluation Date | E40: Status | F40: Notes:
A41: 11A/11B | B41: =TODAY() -> 45945 | C41: 14 | D41: Instruction Date | E41: Trained | F41: Cross Front Right Hand/Cross Front Left Hand
A42: 12A/12B | B42: =TODAY() -> 45945 | C42: 14 | D42: Instruction Date | E42: Trained | F42: Behind Back to Right/Behind Back to Left

Sheet 5 Black Stripes
A1: Promotion Date | C1: Todays Date | D1: =TODAY() -> 45945
A2: Current Rank | B2: 5 Black Stripes | C2: Testing Date | D2: =SUM(D3-(TODAY())) -> -1018
A3: Target Rank | B3: 6 Black Stripes | C3: Days Until Testing | D3: =VLOOKUP(B3,Target,4,0) -> 44927
A5: 6 Black Stripes Requirements | B5: Ready to Test?
A6: Kwahn Juhl Ki
A7: N/A
A9: Theory
B10: Instruction Date | C10: Days Until Eval | D10: Evaluation Date | E10: Status | F10: Notes:
A14: Technique
A15: Kwahn Juhl Ki | B15: Instruction Date | C15: Days Until Eval | D15: Evaluation Date | E15: Status | F15: Notes:
A16: 1 | B16: =TODAY() -> 45945 | C16: 14 | D16: Instruction Date | E16: Untrained
A17: 2 | B17: =TODAY() -> 45945 | C17: 14 | D17: Instruction Date | E17: Untrained
A18: 3 | B18: =TODAY() -> 45945 | C18: 14 | D18: Instruction Date | E18: Untrained
A19: 4 | B19: =TODAY() -> 45945 | C19: 14 | D19: Instruction Date | E19: Untrained
A20: 5 | B20: =TODAY() -> 45945 | C20: 14 | D20: Instruction Date | E20: Untrained
A21: 6 | B21: =TODAY() -> 45945 | C21: 14 | D21: Instruction Date | E21: Untrained
A22: 7 | B22: =TODAY() -> 45945 | C22: 14 | D22: Instruction Date | E22: Untrained
A23: 8 | B23: =TODAY() -> 45945 | C23: 14 | D23: Instruction Date | E23: Untrained
A24: 9 | B24: =TODAY() -> 45945 | C24: 14 | D24: Instruction Date | E24: Untrained
A25: 10 | B25: =TODAY() -> 45945 | C25: 14 | D25: Instruction Date | E25: Untrained
A26: 11 | B26: =TODAY() -> 45945 | C26: 14 | D26: Instruction Date | E26: Untrained
A27: 12 | B27: =TODAY() -> 45945 | C27: 14 | D27: Instruction Date | E27: Untrained
A28: 13 | B28: =TODAY() -> 45945 | C28: 14 | D28: Instruction Date | E28: Untrained
A30: Bohng Dol-liki (Staff Spinning) | B30: Instruction Date | C30: Days Until Eval | D30: Evaluation Date | E30: Status | F30: Notes:
A31: 13A/B
A32: 14A/B | B32: =TODAY() -> 45945 | C32: 14 | D32: Instruction Date | E32: Trained | F32: Overhead Strike Left/Overhead Strike Right
A33: 15A/B | B33: =TODAY() -> 45945 | C33: 14 | D33: Instruction Date | E33: Trained | F33: Behind Neck Spin Right/Behind Neck Spin Left

Sheet 6 Black Stripes
A1: Promotion Date | C1: Todays Date | D1: =TODAY() -> 45945
A2: Current Rank | B2: 6 Black Stripes | C2: Testing Date | D2: =SUM(D3-(TODAY())) -> -928
A3: Target Rank | B3: 7 Black Stripes | C3: Days Until Testing | D3: =VLOOKUP(B3,Target,4,0) -> 45017
A5: 7 Black Stripes Requiremnts | B5: Ready to Test?
A6: Kwahn Juhl Ki
A7: N/A
A9: Theory
B10: Instruction Date | C10: Days Until Eval | D10: Evaluation Date | E10: Status | F10: Notes:
A14: Technique
A15: Too Ki | B15: Instruction Date | C15: Days Until Eval | D15: Evaluation Date | E15: Status | F15: Notes:
A16: 1 | B16: =TODAY() -> 45945 | C16: 14 | D16: Instruction Date | E16: Untrained
A17: 2 | B17: =TODAY() -> 45945 | C17: 14 | D17: Instruction Date | E17: Untrained
A18: 3 | B18: =TODAY() -> 45945 | C18: 14 | D18: Instruction Date | E18: Untrained
A19: 4 | B19: =TODAY() -> 45945 | C19: 14 | D19: Instruction Date | E19: Untrained
A20: 5 | B20: =TODAY() -> 45945 | C20: 14 | D20: Instruction Date | E20: Untrained
A22: Mohk Joh Leu Ki | B22: Instruction Date | C22: Days Until Eval | D22: Evaluation Date | E22: Status | F22: Notes:
A23: 1 | B23: =TODAY() -> 45945 | C23: 14 | D23: Instruction Date | E23: Untrained
A24: 2 | B24: =TODAY() -> 45945 | C24: 14 | D24: Instruction Date | E24: Untrained
A25: 3 | B25: =TODAY() -> 45945 | C25: 14 | D25: Instruction Date | E25: Untrained
A26: 4 | B26: =TODAY() -> 45945 | C26: 14 | D26: Instruction Date | E26: Untrained
A27: 5 | B27: =TODAY() -> 45945 | C27: 14 | D27: Instruction Date | E27: Untrained
A29: Form
A30: Joong Bong Il Hyung | B30: Instruction Date | C30: Days Until Eval | D30: Evaluation Date | E30: Status | F30: Notes:
A31: 1 | B31: =TODAY() -> 45945 | C31: 14 | D31: Instruction Date | E31: In Progress | F31: Three Spins Right
A32: 2 | B32: =TODAY() -> 45945 | C32: 14 | D32: Instruction Date | E32: In Progress | F32: Bow
A33: 3 | B33: =TODAY() -> 45945 | C33: 14 | D33: Instruction Date | E33: In Progress | F33: Step Back
A34: 4 | B34: =TODAY() -> 45945 | C34: 14 | D34: Instruction Date | E34: In Progress | F34: Two Handed Crossover x3
A35: 5 | B35: =TODAY() -> 45945 | C35: 14 | D35: Instruction Date | E35: In Progress | F35: Step up; 1 handed Crossover x 3
A36: 6 | B36: =TODAY() -> 45945 | C36: 14 | D36: Instruction Date | E36: In Progress | F36: Step Back; Spin #5 x 3
A37: 7 | B37: =TODAY() -> 45945 | C37: 14 | D37: Instruction Date | E37: In Progress | F37: Palm Flower
A38: 8 | B38: =TODAY() -> 45945 | C38: 14 | D38: Instruction Date | E38: In Progress | F38: #14a Standing
A39: 9 | B39: =TODAY() -> 45945 | C39: 14 | D39: Instruction Date | E39: In Progress | F39: 14a Kneeling
A40: 10 | B40: =TODAY() -> 45945 | C40: 14 | D40: Instruction Date | E40: In Progress | F40: Stike Left and back
A41: 11 | B41: =TODAY() -> 45945 | C41: 14 | D41: Instruction Date | E41: In Progress | F41: Strike Right and back
A42: 12 | B42: =TODAY() -> 45945 | C42: 14 | D42: Instruction Date | E42: In Progress | F42: Inverted Horizontal strike
... A44: 14 | B44: =TODAY() -> 45945 | C44: 14 | D44: Instruction Date | E44: In Progress | F44: Horzontal Strike while sweeping back left

Sheet 7 Black Stripes
A1: Promotion Date | C1: Todays Date | D1: =TODAY() -> 45945
A2: Current Rank | B2: 7 Black Stripes | C2: Testing Date | D2: =SUM(D3-(TODAY())) -> -838
A3: Target Rank | B3: 8 Black Stripes | C3: Days Until Testing | D3: =VLOOKUP(B3,Target,4,0) -> 45107
A5: 8 Black Stripes | B5: Ready to Test?
A6: Kwahn Juhl Ki
A7: N/A
A9: Theory
B10: Instruction Date | C10: Days Until Eval | D10: Evaluation Date | E10: Status | F10: Notes:
A14: Technique
A15: Bahng Too Ki | B15: Instruction Date | C15: Days Until Eval | D15: Evaluation Date | E15: Status | F15: Notes:
A16: 1 | B16: =TODAY() -> 45945 | C16: 14 | D16: Instruction Date | E16: Untrained
A17: 2 | B17: =TODAY() -> 45945 | C17: 14 | D17: Instruction Date | E17: Untrained
A18: 3 | B18: =TODAY() -> 45945 | C18: 14 | D18: Instruction Date | E18: Untrained
A19: 4 | B19: =TODAY() -> 45945 | C19: 14 | D19: Instruction Date | E19: Untrained
A20: 5 | B20: =TODAY() -> 45945 | C20: 14 | D20: Instruction Date | E20: Untrained
A21: 6 | B21: =TODAY() -> 45945 | C21: 14 | D21: Instruction Date | E21: Untrained
A22: 7 | B22: =TODAY() -> 45945 | C22: 14 | D22: Instruction Date | E22: Untrained
A23: 8 | B23: =TODAY() -> 45945 | C23: 14 | D23: Instruction Date | E23: Untrained
A24: 9 | B24: =TODAY() -> 45945 | C24: 14 | D24: Instruction Date | E24: Untrained
A25: 10 | B25: =TODAY() -> 45945 | C25: 14 | D25: Instruction Date | E25: Untrained
A27: Yahng Sahn Mok Soo | B27: Instruction Date | C27: Days Until Eval | D27: Evaluation Date | E27: Status | F27: Notes:
B28: =TODAY() -> 45945 | C28: 14 | D28: Instruction Date | E28: Untrained
B29: =TODAY() -> 45945 | C29: 14 | D29: Instruction Date | E29: Untrained
B30: =TODAY() -> 45945 | C30: 14 | D30: Instruction Date | E30: Untrained
B31: =TODAY() -> 45945 | C31: 14 | D31: Instruction Date | E31: Untrained
B32: =TODAY() -> 45945 | C32: 14 | D32: Instruction Date | E32: Untrained
B33: =TODAY() -> 45945 | C33: 14 | D33: Instruction Date | E33: Untrained
B34: =TODAY() -> 45945 | C34: 14 | D34: Instruction Date | E34: Untrained
B35: =TODAY() -> 45945 | C35: 14 | D35: Instruction Date | E35: Untrained
A37: Form
A38: Joong Bong Il Hyung | B38: Instruction Date | C38: Days Until Eval | D38: Evaluation Date | E38: Status | F38: Notes:
A39: 15 | B39: =TODAY() -> 45945 | C39: 14 | D39: Instruction Date | E39: In Progress | F39: Palm Flower
