Workbook
Name Target: BIO!$B$9:$E$24

Sheet BIO
A1: Student Name | B1: AnaLiza Gallegos
A2: Date Joined | B2: 43757
A3: Student ID
A4: Tuition Program
A5: Current Rank | B5: Jyokyo Nim | C5: Black Belt
A6: Date of Last Promotion
B8: Belt | C8: Interval | D8: Period | E8: Test Date
A9: Huin ddi | B9: White Belt | C9: 0 | D9: 0
A10: Huin ddi | B10: Yellow Stripe | C10: =SUM(E10-E9) -> 0 | D10: 1
A11: Norang ddi | B11: Yellow Belt | C11: =SUM(E11-E10) -> 0 | D11: 2
A12: Norang ddi | B12: Blue Stripe | C12: =SUM(E12-E11) -> 0 | D12: 3
A13: Cheong ddi | B13: Blue Belt | C13: =SUM(E13-E12) -> 0 | D13: 4
A14: Cheong ddi | B14: Red Stripe | C14: =SUM(E14-E13) -> 0 | D14: 5
A15: Hong ddi | B15: Red Belt | C15: =SUM(E15-E14) -> 0 | D15: 6
A16: Hong ddi | B16: Brown Stripe | C16: =SUM(E16-E15) -> 0 | D16: 7
A17: Ja ddi | B17: Brown Belt | C17: =SUM(E17-E16) -> 0 | D17: 8
A18: Ja ddi | B18: 1 Black Stripe | C18: =SUM(E18-E17) -> 0 | D18: 9
A19: Dahnbo Nim | B19: 2 Black Stripes | C19: =SUM(E19-E18) -> 0 | D19: 10
A20: Dahnbo Nim | B20: 3 Black Stripes | C20: =SUM(E20-E19) -> 0 | D20: 11
A21: Dahnbo Nim | B21: 4 Black Stripes | C21: =SUM(E21-E20) -> 0 | D21: 12
... A24: Jyokyo Nim | B24: Black Belt | C24: =SUM(E24-E23) -> 0 | D24: 15

Sheet Rollup
A1: Start Date | B1: =BIO!$B$2 -> 43757 | C1: Todays Date | D1: =TODAY() -> 45226
A2: Current Rank | B2: =BIO!$C$5 -> Black Belt | C2: Testing Date | D2: =VLOOKUP(B3,Target,4,0) -> 0
A3: Target Rank | B3: Yellow Belt | C3: Days Until Testing | D3: =SUM(D2-(TODAY())) -> -45226
A4: Yellow Stripe Requirments
A5: Etiquette | B5: Instruction Date | C5: Days Until Eval | D5: Evaluation Date | E5: Status | F5: Notes
A6: Bowing
A8: Stances (Jah Se) | B8: Instruction Date | C8: Days Until Eval | D8: Evaluation Date | E8: Status | F8: Nickname
A9: Cha Ryuht | B9: =TODAY() -> 45226 | C9: 14 | D9: =SUM(B9+C9) -> 45240 | E9: Proficient | F9: Attention
A10: Kong Kyuk Jah Se | B10: =TODAY() -> 45226 | C10: 14 | D10: =SUM(B10+C10) -> 45240 | E10: Proficient | F10: Left Fighting Stance
A11: Bahng Uh Jah Se | B11: =TODAY() -> 45226 | C11: 14 | D11: =SUM(B11+C11) -> 45240 | E11: Proficient | F11: Right Fighting Stance
A12: Ki Mah Jah Se | B12: =TODAY() -> 45226 | C12: 14 | D12: =SUM(B12+C12) -> 45240 | E12: Proficient | F12: Horse Stance
A13: Juhn Guhl Jah se | B13: =TODAY() -> 45226 | C13: 14 | D13: =SUM(B13+C13) -> 45240 | E13: Proficient | F13: Front Stance
A15: Technique
A16: Sohnh Ppae Ki 1-5 | B16: Instruction Date | C16: Days Until Eval | D16: Evaluation Date | E16: Status | F16: Nickname | G16: Notes: Always Attack Opponents Thumb; Fingers Open WIDE
A17: 1 | B17: =TODAY() -> 45226 | C17: 14 | D17: =SUM(B17+C17) -> 45240 | E17: Proficient | F17: UP | G17: Thumb Up: Rotate up and out.
A18: 2 | B18: =TODAY() -> 45226 | C18: 14 | D18: =SUM(B18+C18) -> 45240 | E18: Proficient | F18: Left | G18: Thumb Left; Rotate Left Horizontally and out
A19: 3 | B19: =TODAY() -> 45226 | C19: 14 | D19: =SUM(B19+C19) -> 45240 | E19: Proficient | F19: Down | G19: Thumb Down; Rotate forward, down, and out
A20: 4 | B20: =TODAY() -> 45226 | C20: 14 | D20: =SUM(B20+C20) -> 45240 | E20: Proficient | F20: Out | G20: Thumb Right, Palm Up Shoot Out 45 degree
A21: 5 | B21: =TODAY() -> 45226 | C21: 14 | D21: =SUM(B21+C21) -> 45240 | E21: Proficient | F21: Circle | G21: Rotate Clockwise, Knife Edge Left
A23: Yellow Belt Requirments
A24: Technique
A25: Ki Bohn Soo 1-5 | B25: Instruction Date | C25: Days Until Eval | D25: Evaluation Date | E25: Status | F25: Nickname | G25: Notes: Point Fingers Where You Want Opponent to Go.
A26: 1 | B26: =TODAY() -> 45226 | C26: 14 | D26: =SUM(B26+C26) -> 45240 | E26: Proficient | F26: Throw Left
A27: 2 | B27: =TODAY() -> 45226 | C27: 14 | D27: =SUM(B27+C27) -> 45240 | E27: Proficient | F27: Spock Shock
A28: 3 | B28: =TODAY() -> 45226 | C28: 14 | D28: =SUM(B28+C28) -> 45240 | E28: Proficient | F28: Hand Shake-Elbow Drop
A29: 4 | B29: =TODAY() -> 45226 | C29: 14 | D29: =SUM(B29+C29) -> 45240 | E29: Proficient | F29: Throw Right
A30: 5 | B30: =TODAY() -> 45226 | C30: 14 | D30: =SUM(B30+C30) -> 45240 | E30: Proficient | F30: Left Over
A31: 6 | B31: =TODAY() -> 45226 | C31: 14 | D31: =SUM(B31+C31) -> 45240 | E31: Proficient | F31: Sudo-Elbow Chop
A32: 7 | B32: =TODAY() -> 45226 | C32: 14 | D32: =SUM(B32+C32) -> 45240 | E32: Proficient | F32: Shoulder Break
A33: 8 | B33: =TODAY() -> 45226 | C33: 14 | D33: =SUM(B33+C33) -> 45240 | E33: Proficient | F33: Y Grab up
A34: 9 | B34: =TODAY() -> 45226 | C34: 14 | D34: =SUM(B34+C34) -> 45240 | E34: Proficient | F34: Hook Knee
A35: 10 | B35: =TODAY() -> 45226 | C35: 14 | D35: =SUM(B35+C35) -> 45240 | E35: Proficient | F35: Temple Thro
A36: 11 | B36: =TODAY() -> 45226 | C36: 14 | D36: =SUM(B36+C36) -> 45240 | E36: Proficient | F36: Chin Throw
A37: 12 | B37: =TODAY() -> 45226 | C37: 14 | D37: =SUM(B37+C37) -> 45240 | E37: Proficient | F37: Throat
... A40: 15 | B40: =TODAY() -> 45226 | C40: 14 | D40: =SUM(B40+C40) -> 45240 | E40: Proficient | F40: High Low
A42: Form
A43: Ki Cho Hyung 4-6
A44: Form
A45: Ki Cho Hyung 1-3
A46: Ki Cho Hyung 1 | B46: Instruction Date | C46: Days Until Eval | D46: Evaluation Date | E46: Status | F46: Notes:
...

Sheet Testing Chart

Sheet White Belt
A1: Start Date | B1: =BIO!$B$2 -> 43757 | C1: Todays Date | D1: =TODAY() -> 45226
A2: Current Rank | B2: =BIO!$C$5 -> Black Belt | C2: Testing Date | D2: =VLOOKUP(B3,Target,4,0) -> 0
A3: Target Rank | B3: Yellow Belt | C3: Days Until Testing | D3: =SUM(D2-(TODAY())) -> -45226
A5: Yellow Stripe Requirements
A6: Theory
A7: Etiquette | B7: Instruction Date | C7: Days Until Eval | D7: Evaluation Date | E7: Status | F7: Notes: Customs and Courtesies Displayed By Students of Kuk Sool Won in and out of the Do Jahng
A8: Do Jahng Etiquette | B8: =TODAY() -> 45226 | C8: 14 | D8: =SUM(B8+C8) -> 45240 | E8: Proficient | F8: Customs/Courtesies when entering Leaving the School/Mats, Addressing others, Focus,
A9: Bowing | B9: =TODAY() -> 45226 | C9: 14 | D9: =SUM(B9+C9) -> 45240 | E9: Proficient | F9: Types of Bows and occasions involving bowing
A10: Uniforms | B10: =TODAY() -> 45226 | C10: 14 | D10: =SUM(B10+C10) -> 45240 | E10: Proficient | F10: Proper way to wear the uniform
A11: Foundation | B11: Instruction Date | C11: Days Until Eval | D11: Evaluation Date | E11: Status | F11: Notes:
A12: Five Principles of a Warrior | B12: =TODAY() -> 45226 | C12: 14 | D12: =SUM(B12+C12) -> 45240 | E12: Proficient | F12: Moral Character
A13: Technical | B13: Instruction Date | C13: Days Until Eval | D13: Evaluation Date | E13: Status | F13: Notes:
A14: Forms | B14: =TODAY() -> 45226 | C14: 14 | D14: =SUM(B14+C14) -> 45240 | E14: Proficient
A15: Basic Techniques | B15: =TODAY() -> 45226 | C15: 14 | D15: =SUM(B15+C15) -> 45240 | E15: Proficient
A16: Language | B16: Instruction Date | C16: Days Until Eval | D16: Evaluation Date | E16: Status | F16: Notes:
A17: Counting | B17: =TODAY() -> 45226 | C17: 14 | D17: =SUM(B17+C17) -> 45240 | E17: Proficient | F17: Counting in Korean
A18: Names of Hand Attacks | B18: =TODAY() -> 45226 | C18: 14 | D18: =SUM(B18+C18) -> 45240 | E18: Proficient
A20: Technique
A21: Stances (Jah Se) | B21: Instruction Date | C21: Days Until Eval | D21: Evaluation Date | E21: Status | F21: Nickname | G21: Notes: Basic Stances used in Forms and During Techniques; During Practice Stances should be as low as possible
A22: Cha Ryuht | B22: =TODAY() -> 45226 | C22: 14 | D22: =SUM(B22+C22) -> 45240 | E22: Proficient | F22: Attention
A23: Kong Kyuk Jah Se | B23: =TODAY() -> 45226 | C23: 14 | D23: =SUM(B23+C23) -> 45240 | E23: Proficient | F23: Left Fighting Stance
A24: Bahng Uh Jah Se | B24: =TODAY() -> 45226 | C24: 14 | D24: =SUM(B24+C24) -> 45240 | E24: Proficient | F24: Right Fighting Stance
A25: Ki Mah Jah Se | B25: =TODAY() -> 45226 | C25: 14 | D25: =SUM(B25+C25) -> 45240 | E25: Proficient | F25: Horse Stance
A26: Juhn Guhl Jah se | B26: =TODAY() -> 45226 | C26: 14 | D26: =SUM(B26+C26) -> 45240 | E26: Proficient | F26: Front Stance
A27: Crane Stance | B27: =TODAY() -> 45226 | C27: 14 | D27: =SUM(B27+C27) -> 45240 | E27: Proficient | F27: Front Stance
A29: Dahn Juhn Ki (1-6) | B29: Instruction Date | C29: Days Until Eval | D29: Evaluation Date | E29: Status | F29: Nickname | G29: Notes: Breating Excercises
A30: 1 | B30: =TODAY() -> 45226 | C30: 14 | D30: =SUM(B30+C30) -> 45240 | E30: Proficient
A31: 2 | B31: =TODAY() -> 45226 | C31: 14 | D31: =SUM(B31+C31) -> 45240 | E31: Proficient
A33: Ki Cho Jah Ki | B33: Instruction Date | C33: Days Until Eval | D33: Evaluation Date | E33: Status | F33: Notes: "Winging out" Technique to focus and direct the flow of Energy (Ki) through the body
A34: 1 | B34: =TODAY() -> 45226 | C34: 14 | D34: =SUM(B34+C34) -> 45240 | E34: Proficient
A35: 2 | B35: =TODAY() -> 45226 | C35: 14 | D35: =SUM(B35+C35) -> 45240 | E35: Proficient
A36: 3 | B36: =TODAY() -> 45226 | C36: 14 | D36: =SUM(B36+C36) -> 45240 | E36: Proficient
A37: 4 | B37: =TODAY() -> 45226 | C37: 14 | D37: =SUM(B37+C37) -> 45240 | E37: Proficient
A38: 5 | B38: =TODAY() -> 45226 | C38: 14 | D38: =SUM(B38+C38) -> 45240 | E38: Proficient
A39: 6 | B39: =TODAY() -> 45226 | C39: 14 | D39: =SUM(B39+C39) -> 45240 | E39: Proficient
A41: Mohm Puhl Ki | B41: Instruction Date | C41: Days Until Eval | D41: Evaluation Date | E41: Status | F41: Notes: Body Conditioning; Stretches designed to loosen and strengthen the body to withstand the rigors of training
A42: 1-Forward/Back Stretch | B42: =TODAY() -> 45226 | C42: 14 | D42: =SUM(B42+C42) -> 45240 | E42: Proficient
A43: 2-Look Up/Down | B43: =TODAY() -> 45226 | C43: 14 | D43: =SUM(B43+C43) -> 45240 | E43: Proficient
A44: 3-Look Side/Side | B44: =TODAY() -> 45226 | C44: 14 | D44: =SUM(B44+C44) -> 45240 | E44: Proficient
A45: 4-Rotate Head | B45: =TODAY() -> 45226 | C45: 14 | D45: =SUM(B45+C45) -> 45240 | E45: Proficient
...

Sheet Yellow Stripe
A1: Start Date | B1: =BIO!$B$2 -> 43757 | C1: Todays Date | D1: =TODAY() -> 45226
A2: Current Rank | B2: =BIO!$C$5 -> Black Belt | C2: Testing Date | D2: =VLOOKUP(B3,Target,4,0) -> 0
A3: Target Rank | B3: Yellow Belt | C3: Days Until Testing | D3: =SUM(D2-(TODAY())) -> -45226
A5: Yellow Belt Requirments
A7: Theory
A8: Etiquette | B8: Instruction Date | C8: Days Until Eval | D8: Evaluation Date | E8: Status | F8: Notes:
A9: Hwarang Do Sesok O-Gye | B9: =TODAY() -> 45226 | C9: 14 | D9: =SUM(B9+C9) -> 45240 | E9: In Progress | F9: Code Of Ethics
A10: Kuk Sool Won Creed | B10: =TODAY() -> 45226 | C10: 14 | D10: =SUM(B10+C10) -> 45240 | E10: Proficient | F10: Student Oath
A11: Foundation | B11: Instruction Date | C11: Days Until Eval | D11: Evaluation Date | E11: Status | F11: Notes:
A12: You-Won-Hwa | B12: =TODAY() -> 45226 | C12: 14 | D12: =SUM(B12+C12) -> 45240 | E12: In Progress | F12: Water
A13: Technical | B13: Instruction Date | C13: Days Until Eval | D13: Evaluation Date | E13: Status | F13: Notes:
A14: Punching | B14: =TODAY() -> 45226 | C14: 14 | D14: =SUM(B14+C14) -> 45240 | E14: Proficient
A15: Kicking | B15: =TODAY() -> 45226 | C15: 14 | D15: =SUM(B15+C15) -> 45240 | E15: Proficient
A16: Promotions: Belts/Stripes | B16: =TODAY() -> 45226 | C16: 14 | D16: =SUM(B16+C16) -> 45240 | E16: Proficient
A17: Language | B17: Instruction Date | C17: Days Until Eval | D17: Evaluation Date | E17: Status | F17: Notes:
A18: Names and Titles | B18: =TODAY() -> 45226 | C18: 14 | D18: =SUM(B18+C18) -> 45240 | E18: Proficient | F18: Addressing Others
A19: Names of Foots Attacks | B19: =TODAY() -> 45226 | C19: 14 | D19: =SUM(B19+C19) -> 45240 | E19: Proficient | F19: Addressing Others
A21: Technique
A22: Stances (Jah Se) | B22: Instruction Date | C22: Days Until Eval | D22: Evaluation Date | E22: Status | F22: Nickname | G22: Notes: Basic Stances
A23: Dragon Stance | B23: =TODAY() -> 45226 | C23: 14 | D23: =SUM(B23+C23) -> 45240 | E23: Proficient
A24: Cat Stance | B24: =TODAY() -> 45226 | C24: 14 | D24: =SUM(B24+C24) -> 45240 | E24: Proficient
A26: Dahn Juhn Ki | B26: Instruction Date | C26: Days Until Eval | D26: Evaluation Date | E26: Status | F26: Nickname | G26: Notes: Breating Excercises
A27: 3 | B27: =TODAY() -> 45226 | C27: 14 | D27: =SUM(B27+C27) -> 45240 | E27: Proficient
A28: 4 | B28: =TODAY() -> 45226 | C28: 14 | D28: =SUM(B28+C28) -> 45240 | E28: Proficient
A30: Nak Bub | B30: Instruction Date | C30: Days Until Eval | D30: Evaluation Date | E30: Status | F30: Nickname | G30: Notes: Falling Principles
A31: Goh Yahng Ee Nak Bub | B31: =TODAY() -> 45226 | C31: 14 | D31: =SUM(B31+C31) -> 45240 | E31: Proficient | F31: Cat Roll
A32: Doo Sohn Poong Cha | B32: =TODAY() -> 45226 | C32: 14 | D32: =SUM(B32+C32) -> 45240 | E32: Proficient | F32: Cart Wheel
A34: Soo Ki | B34: Instruction Date | C34: Days Until Eval | D34: Evaluation Date | E34: Status | F34: Nickname | G34: Notes: Hand Techniques; Basic attacks of the weaponless hand
A35: Four Winds Block | B35: =TODAY() -> 45226 | C35: 14 | D35: =SUM(B35+C35) -> 45240 | E35: Proficient | F35: Four Winds Block
A36: Double High Knife Block | B36: =TODAY() -> 45226 | C36: 17 | D36: =SUM(B36+C36) -> 45243 | E36: Proficient | F36: Double Outside Knife Strike
A37: One Two Punch | B37: =TODAY() -> 45226 | C37: 17 | D37: =SUM(B37+C37) -> 45243 | E37: Proficient | F37: One Two Punch
A38: Circle Back Fist | B38: =TODAY() -> 45226 | C38: 17 | D38: =SUM(B38+C38) -> 45243 | E38: Proficient | F38: One Two Punch
A39: Vertical Spear Hand Strike | B39: =TODAY() -> 45226 | C39: 14 | D39: =SUM(B39+C39) -> 45240 | E39: Proficient | F39: Vertical Spear Hand Strike
A40: Double Knife Chop | B40: =TODAY() -> 45226 | C40: 14 | D40: =SUM(B40+C40) -> 45240 | E40: Proficient | F40: Double Knife Chop
A41: Parallel-Double Palm Strike | B41: =TODAY() -> 45226 | C41: 14 | D41: =SUM(B41+C41) -> 45240 | E41: Proficient | F41: Parallel-Double Palm Strike
A43: Johk Sool | B43: Instruction Date | C43: Days Until Eval | D43: Evaluation Date | E43: Status | F43: Nickname | G43: Notes: Foot Techniques; Basic attacks using the feet
A44: Knee Kick | B44: =TODAY() -> 45226 | C44: 14 | D44: =SUM(B44+C44) -> 45240 | E44: Proficient | F44: Knee Kick
A45: Round Kick | B45: =TODAY() -> 45226 | C45: 14 | D45: =SUM(B45+C45) -> 45240 | E45: Proficient | F45: Round Kick
A46: Outside Kick | B46: =TODAY() -> 45226 | C46: 14 | D46: =SUM(B46+C46) -> 45240 | E46: Proficient | F46: Outside Kick
A47: Jump Inside Kick | B47: =TODAY() -> 45226 | C47: 14 | D47: =SUM(B47+C47) -> 45240 | E47: Proficient | F47: Jump Inside kick
...

Sheet Yellow Belt
A1: Promotion Date | C1: Todays Date | D1: =TODAY() -> 45226
A2: Current Rank | B2: =BIO!$C$5 -> Black Belt | C2: Testing Date | D2: =VLOOKUP(B2,Target,4,0) -> 0
A3: Target Rank | B3: Blue Belt | C3: Days Until Testing | D3: =SUM(D2-(TODAY())) -> -45226
A5: Blue Stripe Requirments
A6: Theory
A7: Etiquette | B7: Instruction Date | C7: Days Until Eval | D7: Evaluation Date | E7: Status | F7: Nickname | G7: Notes: History, Language,Principles, and Ideology on which all Kuk Sool Won is Founded
A8: Handling Weapons
A9: Sparring
A10: Foundation | B10: Instruction Date | C10: Days Until Eval | D10: Evaluation Date | E10: Status | F10: Nickname | G10: Notes: History, Language,Principles, and Ideology on which all Kuk Sool Won is Founded
